Microsoft Windows [Version 10.0.18363.720]
(c) 2019 Microsoft Corporation. All rights reserved.

C:\Users\SadeedBari>python -m django --version
3.0.5

C:\Users\SadeedBari>cd C:\Users\SadeedBari\Documents\djangoproject

C:\Users\SadeedBari\Documents\djangoproject>django-admin

Type 'django-admin help <subcommand>' for help on a specific subcommand.

Available subcommands:

[django]
    check
    compilemessages
    createcachetable
    dbshell
    diffsettings
    dumpdata
    flush
    inspectdb
    loaddata
    makemessages
    makemigrations
    migrate
    runserver
    sendtestemail
    shell
    showmigrations
    sqlflush
    sqlmigrate
    sqlsequencereset
    squashmigrations
    startapp
    startproject
    test
    testserver
Note that only Django core commands are listed as settings are not properly configured (error: Requested setting INSTALLED_APPS, but settings are not configured. You must either define the environment variable DJANGO_SETTINGS_MODULE or call settings.configure() before accessing settings.).

C:\Users\SadeedBari\Documents\djangoproject>django-admin startproject django_project

C:\Users\SadeedBari\Documents\djangoproject>cd django_project

C:\Users\SadeedBari\Documents\djangoproject\django_project>python manage.py runserver
Watching for file changes with StatReloader
Performing system checks...

System check identified no issues (0 silenced).

You have 17 unapplied migration(s). Your project may not work properly until you apply the migrations for app(s): admin, auth, contenttypes, sessions.
Run 'python manage.py migrate' to apply them.
April 05, 2020 - 19:52:01
Django version 3.0.5, using settings 'django_project.settings'
Starting development server at http://127.0.0.1:8000/
Quit the server with CTRL-BREAK.
[05/Apr/2020 19:52:40] "GET / HTTP/1.1" 200 16351
[05/Apr/2020 19:52:40] "GET /static/admin/css/fonts.css HTTP/1.1" 200 423
[05/Apr/2020 19:52:41] "GET /static/admin/fonts/Roboto-Bold-webfont.woff HTTP/1.1" 200 86184
[05/Apr/2020 19:52:41] "GET /static/admin/fonts/Roboto-Regular-webfont.woff HTTP/1.1" 200 85876
[05/Apr/2020 19:52:41] "GET /static/admin/fonts/Roboto-Light-webfont.woff HTTP/1.1" 200 85692
Not Found: /favicon.ico
[05/Apr/2020 19:52:41] "GET /favicon.ico HTTP/1.1" 404 1980
[05/Apr/2020 19:53:36] "GET / HTTP/1.1" 200 16351
[05/Apr/2020 19:53:36] "GET /static/admin/css/fonts.css HTTP/1.1" 200 423
[05/Apr/2020 19:53:37] "GET /static/admin/fonts/Roboto-Regular-webfont.woff HTTP/1.1" 200 85876
[05/Apr/2020 19:53:37] "GET /static/admin/fonts/Roboto-Light-webfont.woff HTTP/1.1" 200 85692
[05/Apr/2020 19:53:37] "GET /static/admin/fonts/Roboto-Bold-webfont.woff HTTP/1.1" 200 86184
Not Found: /favicon.ico
[05/Apr/2020 19:53:37] "GET /favicon.ico HTTP/1.1" 404 1980
[05/Apr/2020 19:53:48] "GET /admin HTTP/1.1" 301 0
[05/Apr/2020 19:53:48] "GET /admin/ HTTP/1.1" 302 0
[05/Apr/2020 19:53:49] "GET /admin/login/?next=/admin/ HTTP/1.1" 200 1913
[05/Apr/2020 19:53:49] "GET /static/admin/css/base.css HTTP/1.1" 200 16378
[05/Apr/2020 19:53:49] "GET /static/admin/css/login.css HTTP/1.1" 200 1233
[05/Apr/2020 19:53:49] "GET /static/admin/css/responsive.css HTTP/1.1" 200 18052

C:\Users\SadeedBari\Documents\djangoproject\django_project>python manage.py startapp blog

C:\Users\SadeedBari\Documents\djangoproject\django_project>tree
Folder PATH listing for volume Windows
Volume serial number is 708F-D8B3
C:.
├───blog
│   └───migrations
└───django_project
    └───__pycache__

C:\Users\SadeedBari\Documents\djangoproject\django_project>python manage.py runserver
Watching for file changes with StatReloader
Performing system checks...

Exception in thread django-main-thread:
Traceback (most recent call last):
  File "C:\Users\SadeedBari\AppData\Local\Programs\Python\Python38-32\lib\threading.py", line 932, in _bootstrap_inner
    self.run()
  File "C:\Users\SadeedBari\AppData\Local\Programs\Python\Python38-32\lib\threading.py", line 870, in run
    self._target(*self._args, **self._kwargs)
  File "C:\Users\SadeedBari\AppData\Local\Programs\Python\Python38-32\lib\site-packages\django\utils\autoreload.py", line 53, in wrapper
    fn(*args, **kwargs)
  File "C:\Users\SadeedBari\AppData\Local\Programs\Python\Python38-32\lib\site-packages\django\core\management\commands\runserver.py", line 117, in inner_run
    self.check(display_num_errors=True)
  File "C:\Users\SadeedBari\AppData\Local\Programs\Python\Python38-32\lib\site-packages\django\core\management\base.py", line 392, in check
    all_issues = self._run_checks(
  File "C:\Users\SadeedBari\AppData\Local\Programs\Python\Python38-32\lib\site-packages\django\core\management\base.py", line 382, in _run_checks
    return checks.run_checks(**kwargs)
  File "C:\Users\SadeedBari\AppData\Local\Programs\Python\Python38-32\lib\site-packages\django\core\checks\registry.py", line 72, in run_checks
    new_errors = check(app_configs=app_configs)
  File "C:\Users\SadeedBari\AppData\Local\Programs\Python\Python38-32\lib\site-packages\django\core\checks\urls.py", line 13, in check_url_config
    return check_resolver(resolver)
  File "C:\Users\SadeedBari\AppData\Local\Programs\Python\Python38-32\lib\site-packages\django\core\checks\urls.py", line 23, in check_resolver
    return check_method()
  File "C:\Users\SadeedBari\AppData\Local\Programs\Python\Python38-32\lib\site-packages\django\urls\resolvers.py", line 407, in check
    for pattern in self.url_patterns:
  File "C:\Users\SadeedBari\AppData\Local\Programs\Python\Python38-32\lib\site-packages\django\utils\functional.py", line 48, in __get__
    res = instance.__dict__[self.name] = self.func(instance)
  File "C:\Users\SadeedBari\AppData\Local\Programs\Python\Python38-32\lib\site-packages\django\urls\resolvers.py", line 588, in url_patterns
    patterns = getattr(self.urlconf_module, "urlpatterns", self.urlconf_module)
  File "C:\Users\SadeedBari\AppData\Local\Programs\Python\Python38-32\lib\site-packages\django\utils\functional.py", line 48, in __get__
    res = instance.__dict__[self.name] = self.func(instance)
  File "C:\Users\SadeedBari\AppData\Local\Programs\Python\Python38-32\lib\site-packages\django\urls\resolvers.py", line 581, in urlconf_module
    return import_module(self.urlconf_name)
  File "C:\Users\SadeedBari\AppData\Local\Programs\Python\Python38-32\lib\importlib\__init__.py", line 127, in import_module
    return _bootstrap._gcd_import(name[level:], package, level)
  File "<frozen importlib._bootstrap>", line 1014, in _gcd_import
  File "<frozen importlib._bootstrap>", line 991, in _find_and_load
  File "<frozen importlib._bootstrap>", line 975, in _find_and_load_unlocked
  File "<frozen importlib._bootstrap>", line 671, in _load_unlocked
  File "<frozen importlib._bootstrap_external>", line 783, in exec_module
  File "<frozen importlib._bootstrap>", line 219, in _call_with_frames_removed
  File "C:\Users\SadeedBari\Documents\djangoproject\django_project\django_project\urls.py", line 21, in <module>
    path('blog/', include('blog.urls')),
  File "C:\Users\SadeedBari\AppData\Local\Programs\Python\Python38-32\lib\site-packages\django\urls\conf.py", line 34, in include
    urlconf_module = import_module(urlconf_module)
  File "C:\Users\SadeedBari\AppData\Local\Programs\Python\Python38-32\lib\importlib\__init__.py", line 127, in import_module
    return _bootstrap._gcd_import(name[level:], package, level)
  File "<frozen importlib._bootstrap>", line 1014, in _gcd_import
  File "<frozen importlib._bootstrap>", line 991, in _find_and_load
  File "<frozen importlib._bootstrap>", line 975, in _find_and_load_unlocked
  File "<frozen importlib._bootstrap>", line 671, in _load_unlocked
  File "<frozen importlib._bootstrap_external>", line 783, in exec_module
  File "<frozen importlib._bootstrap>", line 219, in _call_with_frames_removed
  File "C:\Users\SadeedBari\Documents\djangoproject\django_project\blog\urls.py", line 20, in <module>
    path('', views.home, name='blog-home'),
AttributeError: module 'blog.views' has no attribute 'home'
C:\Users\SadeedBari\Documents\djangoproject\django_project\blog\views.py changed, reloading.
Watching for file changes with StatReloader
Performing system checks...

System check identified no issues (0 silenced).

You have 17 unapplied migration(s). Your project may not work properly until you apply the migrations for app(s): admin, auth, contenttypes, sessions.
Run 'python manage.py migrate' to apply them.
April 05, 2020 - 20:13:12
Django version 3.0.5, using settings 'django_project.settings'
Starting development server at http://127.0.0.1:8000/
Quit the server with CTRL-BREAK.
Not Found: /
[05/Apr/2020 20:13:22] "GET / HTTP/1.1" 404 2034
[05/Apr/2020 20:14:22] "GET /blog HTTP/1.1" 301 0
[05/Apr/2020 20:14:22] "GET /blog/ HTTP/1.1" 200 18
C:\Users\SadeedBari\Documents\djangoproject\django_project\django_project\urls.py changed, reloading.
Watching for file changes with StatReloader
Performing system checks...

Exception in thread django-main-thread:
Traceback (most recent call last):
  File "C:\Users\SadeedBari\AppData\Local\Programs\Python\Python38-32\lib\threading.py", line 932, in _bootstrap_inner
    self.run()
  File "C:\Users\SadeedBari\AppData\Local\Programs\Python\Python38-32\lib\threading.py", line 870, in run
    self._target(*self._args, **self._kwargs)
  File "C:\Users\SadeedBari\AppData\Local\Programs\Python\Python38-32\lib\site-packages\django\utils\autoreload.py", line 53, in wrapper
    fn(*args, **kwargs)
  File "C:\Users\SadeedBari\AppData\Local\Programs\Python\Python38-32\lib\site-packages\django\core\management\commands\runserver.py", line 117, in inner_run
    self.check(display_num_errors=True)
  File "C:\Users\SadeedBari\AppData\Local\Programs\Python\Python38-32\lib\site-packages\django\core\management\base.py", line 392, in check
    all_issues = self._run_checks(
  File "C:\Users\SadeedBari\AppData\Local\Programs\Python\Python38-32\lib\site-packages\django\core\management\base.py", line 382, in _run_checks
    return checks.run_checks(**kwargs)
  File "C:\Users\SadeedBari\AppData\Local\Programs\Python\Python38-32\lib\site-packages\django\core\checks\registry.py", line 72, in run_checks
    new_errors = check(app_configs=app_configs)
  File "C:\Users\SadeedBari\AppData\Local\Programs\Python\Python38-32\lib\site-packages\django\core\checks\urls.py", line 13, in check_url_config
    return check_resolver(resolver)
  File "C:\Users\SadeedBari\AppData\Local\Programs\Python\Python38-32\lib\site-packages\django\core\checks\urls.py", line 23, in check_resolver
    return check_method()
  File "C:\Users\SadeedBari\AppData\Local\Programs\Python\Python38-32\lib\site-packages\django\urls\resolvers.py", line 407, in check
    for pattern in self.url_patterns:
  File "C:\Users\SadeedBari\AppData\Local\Programs\Python\Python38-32\lib\site-packages\django\utils\functional.py", line 48, in __get__
    res = instance.__dict__[self.name] = self.func(instance)
  File "C:\Users\SadeedBari\AppData\Local\Programs\Python\Python38-32\lib\site-packages\django\urls\resolvers.py", line 588, in url_patterns
    patterns = getattr(self.urlconf_module, "urlpatterns", self.urlconf_module)
  File "C:\Users\SadeedBari\AppData\Local\Programs\Python\Python38-32\lib\site-packages\django\utils\functional.py", line 48, in __get__
    res = instance.__dict__[self.name] = self.func(instance)
  File "C:\Users\SadeedBari\AppData\Local\Programs\Python\Python38-32\lib\site-packages\django\urls\resolvers.py", line 581, in urlconf_module
    return import_module(self.urlconf_name)
  File "C:\Users\SadeedBari\AppData\Local\Programs\Python\Python38-32\lib\importlib\__init__.py", line 127, in import_module
    return _bootstrap._gcd_import(name[level:], package, level)
  File "<frozen importlib._bootstrap>", line 1014, in _gcd_import
  File "<frozen importlib._bootstrap>", line 991, in _find_and_load
  File "<frozen importlib._bootstrap>", line 975, in _find_and_load_unlocked
  File "<frozen importlib._bootstrap>", line 671, in _load_unlocked
  File "<frozen importlib._bootstrap_external>", line 783, in exec_module
  File "<frozen importlib._bootstrap>", line 219, in _call_with_frames_removed
  File "C:\Users\SadeedBari\Documents\djangoproject\django_project\django_project\urls.py", line 22, in <module>
    path('about/', include('about.urls')),
  File "C:\Users\SadeedBari\AppData\Local\Programs\Python\Python38-32\lib\site-packages\django\urls\conf.py", line 34, in include
    urlconf_module = import_module(urlconf_module)
  File "C:\Users\SadeedBari\AppData\Local\Programs\Python\Python38-32\lib\importlib\__init__.py", line 127, in import_module
    return _bootstrap._gcd_import(name[level:], package, level)
  File "<frozen importlib._bootstrap>", line 1014, in _gcd_import
  File "<frozen importlib._bootstrap>", line 991, in _find_and_load
  File "<frozen importlib._bootstrap>", line 961, in _find_and_load_unlocked
  File "<frozen importlib._bootstrap>", line 219, in _call_with_frames_removed
  File "<frozen importlib._bootstrap>", line 1014, in _gcd_import
  File "<frozen importlib._bootstrap>", line 991, in _find_and_load
  File "<frozen importlib._bootstrap>", line 973, in _find_and_load_unlocked
ModuleNotFoundError: No module named 'about'
Traceback (most recent call last):
  File "manage.py", line 21, in <module>
    main()
  File "manage.py", line 17, in main
    execute_from_command_line(sys.argv)
  File "C:\Users\SadeedBari\AppData\Local\Programs\Python\Python38-32\lib\site-packages\django\core\management\__init__.py", line 401, in execute_from_command_line
    utility.execute()
  File "C:\Users\SadeedBari\AppData\Local\Programs\Python\Python38-32\lib\site-packages\django\core\management\__init__.py", line 395, in execute
    self.fetch_command(subcommand).run_from_argv(self.argv)
  File "C:\Users\SadeedBari\AppData\Local\Programs\Python\Python38-32\lib\site-packages\django\core\management\base.py", line 328, in run_from_argv
    self.execute(*args, **cmd_options)
  File "C:\Users\SadeedBari\AppData\Local\Programs\Python\Python38-32\lib\site-packages\django\core\management\commands\runserver.py", line 60, in execute
    super().execute(*args, **options)
  File "C:\Users\SadeedBari\AppData\Local\Programs\Python\Python38-32\lib\site-packages\django\core\management\base.py", line 369, in execute
    output = self.handle(*args, **options)
  File "C:\Users\SadeedBari\AppData\Local\Programs\Python\Python38-32\lib\site-packages\django\core\management\commands\runserver.py", line 95, in handle
    self.run(**options)
  File "C:\Users\SadeedBari\AppData\Local\Programs\Python\Python38-32\lib\site-packages\django\core\management\commands\runserver.py", line 102, in run
    autoreload.run_with_reloader(self.inner_run, **options)
  File "C:\Users\SadeedBari\AppData\Local\Programs\Python\Python38-32\lib\site-packages\django\utils\autoreload.py", line 599, in run_with_reloader
    start_django(reloader, main_func, *args, **kwargs)
  File "C:\Users\SadeedBari\AppData\Local\Programs\Python\Python38-32\lib\site-packages\django\utils\autoreload.py", line 584, in start_django
    reloader.run(django_main_thread)
  File "C:\Users\SadeedBari\AppData\Local\Programs\Python\Python38-32\lib\site-packages\django\utils\autoreload.py", line 299, in run
    self.run_loop()
  File "C:\Users\SadeedBari\AppData\Local\Programs\Python\Python38-32\lib\site-packages\django\utils\autoreload.py", line 305, in run_loop
    next(ticker)
  File "C:\Users\SadeedBari\AppData\Local\Programs\Python\Python38-32\lib\site-packages\django\utils\autoreload.py", line 345, in tick
    for filepath, mtime in self.snapshot_files():
  File "C:\Users\SadeedBari\AppData\Local\Programs\Python\Python38-32\lib\site-packages\django\utils\autoreload.py", line 361, in snapshot_files
    for file in self.watched_files():
  File "C:\Users\SadeedBari\AppData\Local\Programs\Python\Python38-32\lib\site-packages\django\utils\autoreload.py", line 260, in watched_files
    yield from iter_all_python_module_files()
  File "C:\Users\SadeedBari\AppData\Local\Programs\Python\Python38-32\lib\site-packages\django\utils\autoreload.py", line 105, in iter_all_python_module_files
    return iter_modules_and_files(modules, frozenset(_error_files))
  File "C:\Users\SadeedBari\AppData\Local\Programs\Python\Python38-32\lib\site-packages\django\utils\autoreload.py", line 141, in iter_modules_and_files
    resolved_path = path.resolve(strict=True).absolute()
  File "C:\Users\SadeedBari\AppData\Local\Programs\Python\Python38-32\lib\pathlib.py", line 1174, in resolve
    s = self._flavour.resolve(self, strict=strict)
  File "C:\Users\SadeedBari\AppData\Local\Programs\Python\Python38-32\lib\pathlib.py", line 200, in resolve
    return self._ext_to_normal(_getfinalpathname(s))
OSError: [WinError 123] The filename, directory name, or volume label syntax is incorrect: '<frozen importlib._bootstrap>'

C:\Users\SadeedBari\Documents\djangoproject\django_project>python manage.py runserver
Watching for file changes with StatReloader
Performing system checks...

System check identified no issues (0 silenced).

You have 17 unapplied migration(s). Your project may not work properly until you apply the migrations for app(s): admin, auth, contenttypes, sessions.
Run 'python manage.py migrate' to apply them.
April 05, 2020 - 20:21:22
Django version 3.0.5, using settings 'django_project.settings'
Starting development server at http://127.0.0.1:8000/
Quit the server with CTRL-BREAK.
[05/Apr/2020 20:21:27] "GET /blog/about HTTP/1.1" 301 0
[05/Apr/2020 20:21:27] "GET /blog/about/ HTTP/1.1" 200 19
[05/Apr/2020 20:21:33] "GET /blog/ HTTP/1.1" 200 18
C:\Users\SadeedBari\Documents\djangoproject\django_project\django_project\urls.py changed, reloading.
Watching for file changes with StatReloader
Performing system checks...

System check identified no issues (0 silenced).

You have 17 unapplied migration(s). Your project may not work properly until you apply the migrations for app(s): admin, auth, contenttypes, sessions.
Run 'python manage.py migrate' to apply them.
April 05, 2020 - 20:22:53
Django version 3.0.5, using settings 'django_project.settings'
Starting development server at http://127.0.0.1:8000/
Quit the server with CTRL-BREAK.
[05/Apr/2020 20:22:59] "GET /blog_dev/ HTTP/1.1" 200 18
[05/Apr/2020 20:23:03] "GET /blog_dev/about HTTP/1.1" 301 0
[05/Apr/2020 20:23:03] "GET /blog_dev/about/ HTTP/1.1" 200 19
Not Found: /
[05/Apr/2020 20:25:15] "GET / HTTP/1.1" 404 2038
C:\Users\SadeedBari\Documents\djangoproject\django_project\django_project\urls.py changed, reloading.
Watching for file changes with StatReloader
Performing system checks...

System check identified no issues (0 silenced).

You have 17 unapplied migration(s). Your project may not work properly until you apply the migrations for app(s): admin, auth, contenttypes, sessions.
Run 'python manage.py migrate' to apply them.
April 05, 2020 - 20:25:46
Django version 3.0.5, using settings 'django_project.settings'
Starting development server at http://127.0.0.1:8000/
Quit the server with CTRL-BREAK.
[05/Apr/2020 20:25:48] "GET / HTTP/1.1" 200 18
C:\Users\SadeedBari\Documents\djangoproject\django_project\django_project\urls.py changed, reloading.
Watching for file changes with StatReloader
Performing system checks...

System check identified no issues (0 silenced).

You have 17 unapplied migration(s). Your project may not work properly until you apply the migrations for app(s): admin, auth, contenttypes, sessions.
Run 'python manage.py migrate' to apply them.
April 05, 2020 - 20:26:06
Django version 3.0.5, using settings 'django_project.settings'
Starting development server at http://127.0.0.1:8000/
Quit the server with CTRL-BREAK.
C:\Users\SadeedBari\Documents\djangoproject\django_project\django_project\urls.py changed, reloading.
Watching for file changes with StatReloader
Performing system checks...

System check identified no issues (0 silenced).

You have 17 unapplied migration(s). Your project may not work properly until you apply the migrations for app(s): admin, auth, contenttypes, sessions.
Run 'python manage.py migrate' to apply them.
April 05, 2020 - 20:27:28
Django version 3.0.5, using settings 'django_project.settings'
Starting development server at http://127.0.0.1:8000/
Quit the server with CTRL-BREAK.
Not Found: /
[05/Apr/2020 20:27:32] "GET / HTTP/1.1" 404 2033
Not Found: /blog/
[05/Apr/2020 20:27:38] "GET /blog/ HTTP/1.1" 404 2307
C:\Users\SadeedBari\Documents\djangoproject\django_project\django_project\urls.py changed, reloading.
Watching for file changes with StatReloader
Performing system checks...

System check identified no issues (0 silenced).

You have 17 unapplied migration(s). Your project may not work properly until you apply the migrations for app(s): admin, auth, contenttypes, sessions.
Run 'python manage.py migrate' to apply them.
April 05, 2020 - 20:27:49
Django version 3.0.5, using settings 'django_project.settings'
Starting development server at http://127.0.0.1:8000/
Quit the server with CTRL-BREAK.
C:\Users\SadeedBari\Documents\djangoproject\django_project\django_project\urls.py changed, reloading.
Watching for file changes with StatReloader
Performing system checks...

System check identified no issues (0 silenced).

You have 17 unapplied migration(s). Your project may not work properly until you apply the migrations for app(s): admin, auth, contenttypes, sessions.
Run 'python manage.py migrate' to apply them.
April 05, 2020 - 20:27:54
Django version 3.0.5, using settings 'django_project.settings'
Starting development server at http://127.0.0.1:8000/
Quit the server with CTRL-BREAK.
[05/Apr/2020 20:27:54] "GET /blog/ HTTP/1.1" 200 18
C:\Users\SadeedBari\Documents\djangoproject\django_project\blog\views.py changed, reloading.
Watching for file changes with StatReloader
Performing system checks...

System check identified no issues (0 silenced).

You have 17 unapplied migration(s). Your project may not work properly until you apply the migrations for app(s): admin, auth, contenttypes, sessions.
Run 'python manage.py migrate' to apply them.
April 05, 2020 - 20:35:31
Django version 3.0.5, using settings 'django_project.settings'
Starting development server at http://127.0.0.1:8000/
Quit the server with CTRL-BREAK.
C:\Users\SadeedBari\Documents\djangoproject\django_project\blog\views.py changed, reloading.
Watching for file changes with StatReloader
Performing system checks...

System check identified no issues (0 silenced).

You have 17 unapplied migration(s). Your project may not work properly until you apply the migrations for app(s): admin, auth, contenttypes, sessions.
Run 'python manage.py migrate' to apply them.
April 05, 2020 - 20:35:39
Django version 3.0.5, using settings 'django_project.settings'
Starting development server at http://127.0.0.1:8000/
Quit the server with CTRL-BREAK.
[05/Apr/2020 20:35:45] "GET /blog/ HTTP/1.1" 200 17
[05/Apr/2020 20:35:50] "GET /blog/about/ HTTP/1.1" 200 25
C:\Users\SadeedBari\Documents\djangoproject\django_project\django_project\settings.py changed, reloading.
Watching for file changes with StatReloader
Exception in thread django-main-thread:
Traceback (most recent call last):
  File "C:\Users\SadeedBari\AppData\Local\Programs\Python\Python38-32\lib\threading.py", line 932, in _bootstrap_inner
    self.run()
  File "C:\Users\SadeedBari\AppData\Local\Programs\Python\Python38-32\lib\threading.py", line 870, in run
    self._target(*self._args, **self._kwargs)
  File "C:\Users\SadeedBari\AppData\Local\Programs\Python\Python38-32\lib\site-packages\django\utils\autoreload.py", line 53, in wrapper
    fn(*args, **kwargs)
  File "C:\Users\SadeedBari\AppData\Local\Programs\Python\Python38-32\lib\site-packages\django\core\management\commands\runserver.py", line 109, in inner_run
    autoreload.raise_last_exception()
  File "C:\Users\SadeedBari\AppData\Local\Programs\Python\Python38-32\lib\site-packages\django\utils\autoreload.py", line 76, in raise_last_exception
    raise _exception[1]
  File "C:\Users\SadeedBari\AppData\Local\Programs\Python\Python38-32\lib\site-packages\django\core\management\__init__.py", line 357, in execute
    autoreload.check_errors(django.setup)()
  File "C:\Users\SadeedBari\AppData\Local\Programs\Python\Python38-32\lib\site-packages\django\utils\autoreload.py", line 53, in wrapper
    fn(*args, **kwargs)
  File "C:\Users\SadeedBari\AppData\Local\Programs\Python\Python38-32\lib\site-packages\django\__init__.py", line 24, in setup
    apps.populate(settings.INSTALLED_APPS)
  File "C:\Users\SadeedBari\AppData\Local\Programs\Python\Python38-32\lib\site-packages\django\apps\registry.py", line 91, in populate
    app_config = AppConfig.create(entry)
  File "C:\Users\SadeedBari\AppData\Local\Programs\Python\Python38-32\lib\site-packages\django\apps\config.py", line 116, in create
    mod = import_module(mod_path)
  File "C:\Users\SadeedBari\AppData\Local\Programs\Python\Python38-32\lib\importlib\__init__.py", line 127, in import_module
    return _bootstrap._gcd_import(name[level:], package, level)
  File "<frozen importlib._bootstrap>", line 1014, in _gcd_import
  File "<frozen importlib._bootstrap>", line 991, in _find_and_load
  File "<frozen importlib._bootstrap>", line 961, in _find_and_load_unlocked
  File "<frozen importlib._bootstrap>", line 219, in _call_with_frames_removed
  File "<frozen importlib._bootstrap>", line 1014, in _gcd_import
  File "<frozen importlib._bootstrap>", line 991, in _find_and_load
  File "<frozen importlib._bootstrap>", line 970, in _find_and_load_unlocked
ModuleNotFoundError: No module named 'blog.apps.BlogConfigdjango'; 'blog.apps' is not a package
Traceback (most recent call last):
  File "manage.py", line 21, in <module>
    main()
  File "manage.py", line 17, in main
    execute_from_command_line(sys.argv)
  File "C:\Users\SadeedBari\AppData\Local\Programs\Python\Python38-32\lib\site-packages\django\core\management\__init__.py", line 401, in execute_from_command_line
    utility.execute()
  File "C:\Users\SadeedBari\AppData\Local\Programs\Python\Python38-32\lib\site-packages\django\core\management\__init__.py", line 395, in execute
    self.fetch_command(subcommand).run_from_argv(self.argv)
  File "C:\Users\SadeedBari\AppData\Local\Programs\Python\Python38-32\lib\site-packages\django\core\management\base.py", line 328, in run_from_argv
    self.execute(*args, **cmd_options)
  File "C:\Users\SadeedBari\AppData\Local\Programs\Python\Python38-32\lib\site-packages\django\core\management\commands\runserver.py", line 60, in execute
    super().execute(*args, **options)
  File "C:\Users\SadeedBari\AppData\Local\Programs\Python\Python38-32\lib\site-packages\django\core\management\base.py", line 369, in execute
    output = self.handle(*args, **options)
  File "C:\Users\SadeedBari\AppData\Local\Programs\Python\Python38-32\lib\site-packages\django\core\management\commands\runserver.py", line 95, in handle
    self.run(**options)
  File "C:\Users\SadeedBari\AppData\Local\Programs\Python\Python38-32\lib\site-packages\django\core\management\commands\runserver.py", line 102, in run
    autoreload.run_with_reloader(self.inner_run, **options)
  File "C:\Users\SadeedBari\AppData\Local\Programs\Python\Python38-32\lib\site-packages\django\utils\autoreload.py", line 599, in run_with_reloader
    start_django(reloader, main_func, *args, **kwargs)
  File "C:\Users\SadeedBari\AppData\Local\Programs\Python\Python38-32\lib\site-packages\django\utils\autoreload.py", line 584, in start_django
    reloader.run(django_main_thread)
  File "C:\Users\SadeedBari\AppData\Local\Programs\Python\Python38-32\lib\site-packages\django\utils\autoreload.py", line 299, in run
    self.run_loop()
  File "C:\Users\SadeedBari\AppData\Local\Programs\Python\Python38-32\lib\site-packages\django\utils\autoreload.py", line 305, in run_loop
    next(ticker)
  File "C:\Users\SadeedBari\AppData\Local\Programs\Python\Python38-32\lib\site-packages\django\utils\autoreload.py", line 345, in tick
    for filepath, mtime in self.snapshot_files():
  File "C:\Users\SadeedBari\AppData\Local\Programs\Python\Python38-32\lib\site-packages\django\utils\autoreload.py", line 361, in snapshot_files
    for file in self.watched_files():
  File "C:\Users\SadeedBari\AppData\Local\Programs\Python\Python38-32\lib\site-packages\django\utils\autoreload.py", line 260, in watched_files
    yield from iter_all_python_module_files()
  File "C:\Users\SadeedBari\AppData\Local\Programs\Python\Python38-32\lib\site-packages\django\utils\autoreload.py", line 105, in iter_all_python_module_files
    return iter_modules_and_files(modules, frozenset(_error_files))
  File "C:\Users\SadeedBari\AppData\Local\Programs\Python\Python38-32\lib\site-packages\django\utils\autoreload.py", line 141, in iter_modules_and_files
    resolved_path = path.resolve(strict=True).absolute()
  File "C:\Users\SadeedBari\AppData\Local\Programs\Python\Python38-32\lib\pathlib.py", line 1174, in resolve
    s = self._flavour.resolve(self, strict=strict)
  File "C:\Users\SadeedBari\AppData\Local\Programs\Python\Python38-32\lib\pathlib.py", line 200, in resolve
    return self._ext_to_normal(_getfinalpathname(s))
OSError: [WinError 123] The filename, directory name, or volume label syntax is incorrect: '<frozen importlib._bootstrap>'

C:\Users\SadeedBari\Documents\djangoproject\django_project>python manage.py runserver
Watching for file changes with StatReloader
Performing system checks...

System check identified no issues (0 silenced).

You have 17 unapplied migration(s). Your project may not work properly until you apply the migrations for app(s): admin, auth, contenttypes, sessions.
Run 'python manage.py migrate' to apply them.
April 05, 2020 - 20:50:16
Django version 3.0.5, using settings 'django_project.settings'
Starting development server at http://127.0.0.1:8000/
Quit the server with CTRL-BREAK.
[05/Apr/2020 20:50:20] "GET /blog/ HTTP/1.1" 200 109
C:\Users\SadeedBari\Documents\djangoproject\django_project\blog\views.py changed, reloading.
Watching for file changes with StatReloader
Performing system checks...

System check identified no issues (0 silenced).

You have 17 unapplied migration(s). Your project may not work properly until you apply the migrations for app(s): admin, auth, contenttypes, sessions.
Run 'python manage.py migrate' to apply them.
April 05, 2020 - 20:51:45
Django version 3.0.5, using settings 'django_project.settings'
Starting development server at http://127.0.0.1:8000/
Quit the server with CTRL-BREAK.
C:\Users\SadeedBari\Documents\djangoproject\django_project\blog\views.py changed, reloading.
Watching for file changes with StatReloader
Performing system checks...

System check identified no issues (0 silenced).

You have 17 unapplied migration(s). Your project may not work properly until you apply the migrations for app(s): admin, auth, contenttypes, sessions.
Run 'python manage.py migrate' to apply them.
April 05, 2020 - 20:52:04
Django version 3.0.5, using settings 'django_project.settings'
Starting development server at http://127.0.0.1:8000/
Quit the server with CTRL-BREAK.
[05/Apr/2020 20:52:08] "GET /blog/ HTTP/1.1" 200 109
[05/Apr/2020 20:52:14] "GET /blog/about/ HTTP/1.1" 200 111
C:\Users\SadeedBari\Documents\djangoproject\django_project\blog\views.py changed, reloading.
Watching for file changes with StatReloader
Performing system checks...

System check identified no issues (0 silenced).

You have 17 unapplied migration(s). Your project may not work properly until you apply the migrations for app(s): admin, auth, contenttypes, sessions.
Run 'python manage.py migrate' to apply them.
April 05, 2020 - 20:56:52
Django version 3.0.5, using settings 'django_project.settings'
Starting development server at http://127.0.0.1:8000/
Quit the server with CTRL-BREAK.
[05/Apr/2020 21:00:11] "GET /blog/about/ HTTP/1.1" 200 111
[05/Apr/2020 21:00:11] "GET /blog/ HTTP/1.1" 200 240
[05/Apr/2020 21:02:42] "GET /blog/ HTTP/1.1" 200 258
C:\Users\SadeedBari\Documents\djangoproject\django_project\blog\views.py changed, reloading.
Watching for file changes with StatReloader
Performing system checks...

System check identified no issues (0 silenced).

You have 17 unapplied migration(s). Your project may not work properly until you apply the migrations for app(s): admin, auth, contenttypes, sessions.
Run 'python manage.py migrate' to apply them.
April 05, 2020 - 21:03:09
Django version 3.0.5, using settings 'django_project.settings'
Starting development server at http://127.0.0.1:8000/
Quit the server with CTRL-BREAK.
[05/Apr/2020 21:03:15] "GET /blog/ HTTP/1.1" 200 240
C:\Users\SadeedBari\Documents\djangoproject\django_project\blog\views.py changed, reloading.
Watching for file changes with StatReloader
Performing system checks...

System check identified no issues (0 silenced).

You have 17 unapplied migration(s). Your project may not work properly until you apply the migrations for app(s): admin, auth, contenttypes, sessions.
Run 'python manage.py migrate' to apply them.
April 05, 2020 - 21:03:44
Django version 3.0.5, using settings 'django_project.settings'
Starting development server at http://127.0.0.1:8000/
Quit the server with CTRL-BREAK.
[05/Apr/2020 21:03:49] "GET /blog/ HTTP/1.1" 200 268
C:\Users\SadeedBari\Documents\djangoproject\django_project\blog\views.py changed, reloading.
Watching for file changes with StatReloader
Performing system checks...

System check identified no issues (0 silenced).

You have 17 unapplied migration(s). Your project may not work properly until you apply the migrations for app(s): admin, auth, contenttypes, sessions.
Run 'python manage.py migrate' to apply them.
April 05, 2020 - 21:08:43
Django version 3.0.5, using settings 'django_project.settings'
Starting development server at http://127.0.0.1:8000/
Quit the server with CTRL-BREAK.
[05/Apr/2020 21:08:45] "GET /blog/ HTTP/1.1" 200 284
[05/Apr/2020 21:08:58] "GET /blog/about/ HTTP/1.1" 200 135
[05/Apr/2020 21:09:31] "GET /blog/about/ HTTP/1.1" 200 135
[05/Apr/2020 21:09:50] "GET /blog/about/ HTTP/1.1" 200 135
[05/Apr/2020 21:10:10] "GET /blog/ HTTP/1.1" 200 284
[05/Apr/2020 21:16:21] "GET /blog/about/ HTTP/1.1" 200 137
[05/Apr/2020 21:16:23] "GET /blog/ HTTP/1.1" 200 285
[05/Apr/2020 21:16:26] "GET /blog/about/ HTTP/1.1" 200 137
[05/Apr/2020 21:21:33] "GET /blog/about/ HTTP/1.1" 200 1255
[05/Apr/2020 21:21:36] "GET /blog/ HTTP/1.1" 200 1403
[05/Apr/2020 21:34:10] "GET /blog/about/ HTTP/1.1" 200 2773
[05/Apr/2020 21:34:10] "GET /static/blog/main.css HTTP/1.1" 404 1665
[05/Apr/2020 21:34:26] "GET /blog/ HTTP/1.1" 200 2921
[05/Apr/2020 21:34:26] "GET /static/blog/main.css HTTP/1.1" 404 1665

C:\Users\SadeedBari\Documents\djangoproject\django_project>python manage.py runserver
Watching for file changes with StatReloader
Performing system checks...

System check identified no issues (0 silenced).

You have 17 unapplied migration(s). Your project may not work properly until you apply the migrations for app(s): admin, auth, contenttypes, sessions.
Run 'python manage.py migrate' to apply them.
April 05, 2020 - 21:34:54
Django version 3.0.5, using settings 'django_project.settings'
Starting development server at http://127.0.0.1:8000/
Quit the server with CTRL-BREAK.
[05/Apr/2020 21:34:57] "GET /blog/ HTTP/1.1" 200 2921
[05/Apr/2020 21:34:57] "GET /static/blog/main.css HTTP/1.1" 200 1207
[05/Apr/2020 21:35:03] "GET /blog/about/ HTTP/1.1" 200 2773
[05/Apr/2020 21:37:02] "GET /blog/about/ HTTP/1.1" 200 2773
[05/Apr/2020 21:37:02] "GET /static/blog/main.css HTTP/1.1" 304 0
[05/Apr/2020 21:37:04] "GET /blog/ HTTP/1.1" 200 3443
[05/Apr/2020 21:37:04] "GET /blog/ HTTP/1.1" 200 3443
[05/Apr/2020 21:43:46] "GET /blog/about/ HTTP/1.1" 200 2789
[05/Apr/2020 21:43:46] "GET /static/blog/main.css HTTP/1.1" 304 0
[05/Apr/2020 21:43:48] "GET /blog/ HTTP/1.1" 200 3459
[05/Apr/2020 21:43:53] "GET /blog/about/ HTTP/1.1" 200 2789
[05/Apr/2020 21:45:04] "GET /blog/ HTTP/1.1" 200 3456
[05/Apr/2020 21:45:04] "GET /static/blog/main.css HTTP/1.1" 304 0
[05/Apr/2020 21:45:05] "GET /blog/ HTTP/1.1" 200 3456
[05/Apr/2020 21:45:51] "GET /blog/ HTTP/1.1" 200 3457
[05/Apr/2020 21:46:46] "GET /blog/about/ HTTP/1.1" 200 2786
[05/Apr/2020 21:46:46] "GET /static/blog/main.css HTTP/1.1" 304 0
[05/Apr/2020 21:47:13] "GET /blog/about/ HTTP/1.1" 200 2787
[05/Apr/2020 21:47:22] "GET /blog/ HTTP/1.1" 200 3460
[05/Apr/2020 22:06:17] "GET /blog/ HTTP/1.1" 200 3460
[05/Apr/2020 22:06:17] "GET /static/blog/main.css HTTP/1.1" 304 0
[05/Apr/2020 22:06:23] "GET /blog/about/ HTTP/1.1" 200 2789
Not Found: /blog/admin
[05/Apr/2020 22:06:24] "GET /blog/admin HTTP/1.1" 404 2324
[05/Apr/2020 22:06:31] "GET /admin/ HTTP/1.1" 302 0
[05/Apr/2020 22:06:31] "GET /admin/login/?next=/admin/ HTTP/1.1" 200 1913
[05/Apr/2020 22:06:31] "GET /static/admin/css/base.css HTTP/1.1" 304 0
[05/Apr/2020 22:06:31] "GET /static/admin/css/login.css HTTP/1.1" 304 0
[05/Apr/2020 22:06:31] "GET /static/admin/css/responsive.css HTTP/1.1" 304 0
[05/Apr/2020 22:06:31] "GET /static/admin/css/fonts.css HTTP/1.1" 304 0
[05/Apr/2020 22:06:32] "GET /static/admin/fonts/Roboto-Regular-webfont.woff HTTP/1.1" 304 0
[05/Apr/2020 22:06:32] "GET /static/admin/fonts/Roboto-Light-webfont.woff HTTP/1.1" 304 0

C:\Users\SadeedBari\Documents\djangoproject\django_project>python manage.py makemigrations
No changes detected

C:\Users\SadeedBari\Documents\djangoproject\django_project>python manage.py runmigrate
Unknown command: 'runmigrate'. Did you mean migrate?
Type 'manage.py help' for usage.

C:\Users\SadeedBari\Documents\djangoproject\django_project>python manage.py migrate
Operations to perform:
  Apply all migrations: admin, auth, contenttypes, sessions
Running migrations:
  Applying contenttypes.0001_initial... OK
  Applying auth.0001_initial... OK
  Applying admin.0001_initial... OK
  Applying admin.0002_logentry_remove_auto_add... OK
  Applying admin.0003_logentry_add_action_flag_choices... OK
  Applying contenttypes.0002_remove_content_type_name... OK
  Applying auth.0002_alter_permission_name_max_length... OK
  Applying auth.0003_alter_user_email_max_length... OK
  Applying auth.0004_alter_user_username_opts... OK
  Applying auth.0005_alter_user_last_login_null... OK
  Applying auth.0006_require_contenttypes_0002... OK
  Applying auth.0007_alter_validators_add_error_messages... OK
  Applying auth.0008_alter_user_username_max_length... OK
  Applying auth.0009_alter_user_last_name_max_length... OK
  Applying auth.0010_alter_group_name_max_length... OK
  Applying auth.0011_update_proxy_permissions... OK
  Applying sessions.0001_initial... OK

C:\Users\SadeedBari\Documents\djangoproject\django_project>python manage.py createsuperuser
Username (leave blank to use 'sadeedbari'): sadeedbari
Email address: sadeedbari@gmail.com
Password:
Password (again):
Superuser created successfully.

C:\Users\SadeedBari\Documents\djangoproject\django_project>python manage.py runserver
Watching for file changes with StatReloader
Performing system checks...

System check identified no issues (0 silenced).
April 05, 2020 - 22:11:24
Django version 3.0.5, using settings 'django_project.settings'
Starting development server at http://127.0.0.1:8000/
Quit the server with CTRL-BREAK.
[05/Apr/2020 22:11:35] "POST /admin/login/?next=/admin/ HTTP/1.1" 302 0
[05/Apr/2020 22:11:35] "GET /admin/ HTTP/1.1" 200 3047
[05/Apr/2020 22:11:35] "GET /static/admin/css/dashboard.css HTTP/1.1" 200 412
[05/Apr/2020 22:11:35] "GET /static/admin/img/icon-addlink.svg HTTP/1.1" 200 331
[05/Apr/2020 22:11:35] "GET /static/admin/img/icon-changelink.svg HTTP/1.1" 200 380
[05/Apr/2020 22:11:35] "GET /static/admin/fonts/Roboto-Bold-webfont.woff HTTP/1.1" 304 0
[05/Apr/2020 22:12:28] "GET /admin/auth/user/ HTTP/1.1" 200 6624
[05/Apr/2020 22:12:28] "GET /static/admin/css/changelists.css HTTP/1.1" 200 6190
[05/Apr/2020 22:12:28] "GET /admin/jsi18n/ HTTP/1.1" 200 3223
[05/Apr/2020 22:12:28] "GET /static/admin/js/jquery.init.js HTTP/1.1" 200 363
[05/Apr/2020 22:12:28] "GET /static/admin/js/core.js HTTP/1.1" 200 5723
[05/Apr/2020 22:12:28] "GET /static/admin/js/admin/RelatedObjectLookups.js HTTP/1.1" 200 6918
[05/Apr/2020 22:12:28] "GET /static/admin/js/actions.js HTTP/1.1" 200 6766
[05/Apr/2020 22:12:28] "GET /static/admin/js/urlify.js HTTP/1.1" 200 8941
[05/Apr/2020 22:12:28] "GET /static/admin/js/vendor/jquery/jquery.js HTTP/1.1" 200 280364
[05/Apr/2020 22:12:28] "GET /static/admin/js/prepopulate.js HTTP/1.1" 200 1530
[05/Apr/2020 22:12:28] "GET /static/admin/img/search.svg HTTP/1.1" 200 458
[05/Apr/2020 22:12:28] "GET /static/admin/js/vendor/xregexp/xregexp.js HTTP/1.1" 200 128820
[05/Apr/2020 22:12:28] "GET /static/admin/img/icon-yes.svg HTTP/1.1" 200 436
[05/Apr/2020 22:12:28] "GET /static/admin/img/tooltag-add.svg HTTP/1.1" 200 331
[05/Apr/2020 22:12:28] "GET /static/admin/img/sorting-icons.svg HTTP/1.1" 200 1097
[05/Apr/2020 22:12:52] "GET /admin/auth/ HTTP/1.1" 200 2973
[05/Apr/2020 22:12:54] "GET /admin/auth/group/ HTTP/1.1" 200 3507
[05/Apr/2020 22:12:54] "GET /admin/jsi18n/ HTTP/1.1" 200 3223
[05/Apr/2020 22:12:57] "GET /admin/auth/ HTTP/1.1" 200 2973
[05/Apr/2020 22:12:59] "GET /admin/auth/user/ HTTP/1.1" 200 6624
[05/Apr/2020 22:12:59] "GET /admin/jsi18n/ HTTP/1.1" 200 3223
[05/Apr/2020 22:13:09] "GET /admin/auth/user/1/change/ HTTP/1.1" 200 14018
[05/Apr/2020 22:13:09] "GET /admin/jsi18n/ HTTP/1.1" 200 3223
[05/Apr/2020 22:13:09] "GET /static/admin/css/forms.css HTTP/1.1" 200 8518
[05/Apr/2020 22:13:09] "GET /static/admin/js/calendar.js HTTP/1.1" 200 7777
[05/Apr/2020 22:13:09] "GET /static/admin/js/admin/DateTimeShortcuts.js HTTP/1.1" 200 20232
[05/Apr/2020 22:13:09] "GET /static/admin/js/SelectBox.js HTTP/1.1" 200 5753
[05/Apr/2020 22:13:09] "GET /static/admin/js/SelectFilter2.js HTTP/1.1" 200 12318
[05/Apr/2020 22:13:09] "GET /static/admin/js/change_form.js HTTP/1.1" 200 712
[05/Apr/2020 22:13:10] "GET /static/admin/css/widgets.css HTTP/1.1" 200 10322
[05/Apr/2020 22:13:10] "GET /static/admin/js/prepopulate_init.js HTTP/1.1" 200 495
[05/Apr/2020 22:13:10] "GET /static/admin/img/icon-clock.svg HTTP/1.1" 200 677
[05/Apr/2020 22:13:10] "GET /static/admin/img/icon-calendar.svg HTTP/1.1" 200 1086
[05/Apr/2020 22:13:10] "GET /static/admin/img/icon-unknown.svg HTTP/1.1" 200 655
[05/Apr/2020 22:13:10] "GET /static/admin/img/icon-unknown-alt.svg HTTP/1.1" 200 655
[05/Apr/2020 22:13:10] "GET /static/admin/img/selector-icons.svg HTTP/1.1" 200 3291
[05/Apr/2020 22:14:02] "GET /admin/auth/ HTTP/1.1" 200 2973
[05/Apr/2020 22:14:09] "GET /admin/auth/user/ HTTP/1.1" 200 6624
[05/Apr/2020 22:14:09] "GET /admin/jsi18n/ HTTP/1.1" 200 3223
[05/Apr/2020 22:14:11] "GET /admin/auth/user/add/ HTTP/1.1" 200 5758
[05/Apr/2020 22:14:11] "GET /admin/jsi18n/ HTTP/1.1" 200 3223
[05/Apr/2020 22:14:26] "POST /admin/auth/user/add/ HTTP/1.1" 200 5937
[05/Apr/2020 22:14:26] "GET /admin/jsi18n/ HTTP/1.1" 200 3223
[05/Apr/2020 22:14:51] "POST /admin/auth/user/add/ HTTP/1.1" 200 5932
[05/Apr/2020 22:14:51] "GET /admin/jsi18n/ HTTP/1.1" 200 3223
[05/Apr/2020 22:15:03] "POST /admin/auth/user/add/ HTTP/1.1" 302 0
[05/Apr/2020 22:15:03] "GET /admin/auth/user/2/change/ HTTP/1.1" 200 14136
[05/Apr/2020 22:15:03] "GET /admin/jsi18n/ HTTP/1.1" 200 3223
[05/Apr/2020 22:16:07] "GET /admin/auth/user/ HTTP/1.1" 200 7040
[05/Apr/2020 22:16:07] "GET /admin/jsi18n/ HTTP/1.1" 200 3223
[05/Apr/2020 22:16:07] "GET /static/admin/img/icon-no.svg HTTP/1.1" 200 560
[05/Apr/2020 22:16:11] "GET /admin/auth/user/2/change/ HTTP/1.1" 200 13929
[05/Apr/2020 22:16:11] "GET /admin/jsi18n/ HTTP/1.1" 200 3223
[05/Apr/2020 22:16:32] "GET /admin/auth/ HTTP/1.1" 200 2973
[05/Apr/2020 22:16:36] "GET /admin/auth/user/ HTTP/1.1" 200 7040
[05/Apr/2020 22:16:36] "GET /admin/jsi18n/ HTTP/1.1" 200 3223
[05/Apr/2020 22:16:39] "GET /admin/auth/ HTTP/1.1" 200 2973
C:\Users\SadeedBari\Documents\djangoproject\django_project\blog\models.py changed, reloading.
Watching for file changes with StatReloader
Performing system checks...

System check identified no issues (0 silenced).
April 05, 2020 - 22:28:04
Django version 3.0.5, using settings 'django_project.settings'
Starting development server at http://127.0.0.1:8000/
Quit the server with CTRL-BREAK.

C:\Users\SadeedBari\Documents\djangoproject\django_project>python manage.py makemigrations
Migrations for 'blog':
  blog\migrations\0001_initial.py
    - Create model Post

C:\Users\SadeedBari\Documents\djangoproject\django_project>python manage.py sqlmigrate blog 0001
BEGIN;
--
-- Create model Post
--
CREATE TABLE "blog_post" ("id" integer NOT NULL PRIMARY KEY AUTOINCREMENT, "title" varchar(100) NOT NULL, "content" text NOT NULL, "date_posted" datetime NOT NULL, "author_id" integer NOT NULL REFERENCES "auth_user" ("id") DEFERRABLE INITIALLY DEFERRED);
CREATE INDEX "blog_post_author_id_dd7a8485" ON "blog_post" ("author_id");
COMMIT;

C:\Users\SadeedBari\Documents\djangoproject\django_project>python manage.py migrate
Operations to perform:
  Apply all migrations: admin, auth, blog, contenttypes, sessions
Running migrations:
  Applying blog.0001_initial... OK

C:\Users\SadeedBari\Documents\djangoproject\django_project>python manage.py shell
Python 3.8.1 (tags/v3.8.1:1b293b6, Dec 18 2019, 22:39:24) [MSC v.1916 32 bit (Intel)] on win32
Type "help", "copyright", "credits" or "license" for more information.
(InteractiveConsole)
>>> from blog.models import Post
>>> from django.contrib.auth.models import users
Traceback (most recent call last):
  File "<console>", line 1, in <module>
ImportError: cannot import name 'users' from 'django.contrib.auth.models' (C:\Users\SadeedBari\AppData\Local\Programs\Python\Python38-32\lib\site-packages\django\contrib\auth\models.py)
>>> from django.contrib.auth.models import User
>>> User.objects.all()
<QuerySet [<User: sadeedbari>, <User: yanani>]>
>>> User.objects.filter(username='sadeedbari')
<QuerySet [<User: sadeedbari>]>
>>> User.objects.filter(username='sadeedbari').first
<bound method QuerySet.first of <QuerySet [<User: sadeedbari>]>>
>>> User.objects.filter(username='sadeedbari').first()
<User: sadeedbari>
>>> user = User.objects.filter(username='sadeedbari').first()
>>> user
<User: sadeedbari>
>>> user.id
1
>>> user.pk
1
>>> user = User.objects.get()
Traceback (most recent call last):
  File "<console>", line 1, in <module>
  File "C:\Users\SadeedBari\AppData\Local\Programs\Python\Python38-32\lib\site-packages\django\db\models\manager.py", line 82, in manager_method
    return getattr(self.get_queryset(), name)(*args, **kwargs)
  File "C:\Users\SadeedBari\AppData\Local\Programs\Python\Python38-32\lib\site-packages\django\db\models\query.py", line 419, in get
    raise self.model.MultipleObjectsReturned(
django.contrib.auth.models.User.MultipleObjectsReturned: get() returned more than one User -- it returned 2!
>>> user = User.objects.get(id=1)
>>> user
<User: sadeedbari>
>>> Post.ojects.all()
Traceback (most recent call last):
  File "<console>", line 1, in <module>
AttributeError: type object 'Post' has no attribute 'ojects'
>>> post_1 = Post(title='Blog 1', content='First Post Content Ever!!', author=user)
>>> Post.ojects.all()
Traceback (most recent call last):
  File "<console>", line 1, in <module>
AttributeError: type object 'Post' has no attribute 'ojects'
>>> Post.objects.all()
<QuerySet []>
>>> post_1.save()
>>> Post.objects.all()
<QuerySet [<Post: Post object (1)>]>
>>> exit()

C:\Users\SadeedBari\Documents\djangoproject\django_project>python manage.py shell
Python 3.8.1 (tags/v3.8.1:1b293b6, Dec 18 2019, 22:39:24) [MSC v.1916 32 bit (Intel)] on win32
Type "help", "copyright", "credits" or "license" for more information.
(InteractiveConsole)
>>> from blog.models import Post
>>> from django.contrib.auth.models import User
>>> Post.objects.all()
<QuerySet [<Post: Blog 1>]>
>>> user = User.objects.filter(username='sadeedbari').first()
>>> user
<User: sadeedbari>
>>> post_2 = Post(title='Blog 2', content='Second post content', author_id=user.id)
>>> post_2.save()
>>> Post.objects.a;;()
  File "<console>", line 1
    Post.objects.a;;()
                   ^
SyntaxError: invalid syntax
>>> Post.objects.all()
<QuerySet [<Post: Blog 1>, <Post: Blog 2>]>
>>> post = Post.objects.first()
>>> post.content
'First Post Content Ever!!'
>>> post_date_posted
Traceback (most recent call last):
  File "<console>", line 1, in <module>
NameError: name 'post_date_posted' is not defined
>>> post.date_posted
datetime.datetime(2020, 4, 6, 2, 37, 50, 526725, tzinfo=<UTC>)
>>> post.author
<User: sadeedbari>
>>> user.email()
Traceback (most recent call last):
  File "<console>", line 1, in <module>
TypeError: 'str' object is not callable
>>> post.author.email
'sadeedbari@gmail.com'
>>> user.post_sat
Traceback (most recent call last):
  File "<console>", line 1, in <module>
AttributeError: 'User' object has no attribute 'post_sat'
>>> user.post_set
<django.db.models.fields.related_descriptors.create_reverse_many_to_one_manager.<locals>.RelatedManager object at 0x03FD3088>
>>> user.post_set.all()
<QuerySet [<Post: Blog 1>, <Post: Blog 2>]>
>>> user.post_set
<django.db.models.fields.related_descriptors.create_reverse_many_to_one_manager.<locals>.RelatedManager object at 0x03FD3088>
>>> user.post_set.all()
<QuerySet [<Post: Blog 1>, <Post: Blog 2>]>
>>> user.post_set.create(title='Blog 3', content='third post content :)')
<Post: Blog 3>
>>> Post.objects.all()
<QuerySet [<Post: Blog 1>, <Post: Blog 2>, <Post: Blog 3>]>
>>> exit()

C:\Users\SadeedBari\Documents\djangoproject\django_project>python manage.py runserver
Watching for file changes with StatReloader
Performing system checks...

System check identified no issues (0 silenced).
April 05, 2020 - 22:52:23
Django version 3.0.5, using settings 'django_project.settings'
Starting development server at http://127.0.0.1:8000/
Quit the server with CTRL-BREAK.
Not Found: /
[05/Apr/2020 22:52:30] "GET / HTTP/1.1" 404 2034
[05/Apr/2020 22:52:34] "GET /blog/ HTTP/1.1" 200 3842
[05/Apr/2020 22:52:34] "GET /static/blog/main.css HTTP/1.1" 304 0
[05/Apr/2020 22:56:11] "GET /blog/ HTTP/1.1" 200 3812
C:\Users\SadeedBari\Documents\djangoproject\django_project\blog\admin.py changed, reloading.
Watching for file changes with StatReloader
Performing system checks...

System check identified no issues (0 silenced).
April 05, 2020 - 22:58:47
Django version 3.0.5, using settings 'django_project.settings'
Starting development server at http://127.0.0.1:8000/
Quit the server with CTRL-BREAK.
[05/Apr/2020 22:58:53] "GET /admin/ HTTP/1.1" 200 4010
[05/Apr/2020 22:58:53] "GET /static/admin/css/base.css HTTP/1.1" 304 0
[05/Apr/2020 22:58:53] "GET /static/admin/css/responsive.css HTTP/1.1" 304 0
[05/Apr/2020 22:58:54] "GET /static/admin/css/fonts.css HTTP/1.1" 304 0
[05/Apr/2020 22:58:54] "GET /static/admin/fonts/Roboto-Regular-webfont.woff HTTP/1.1" 304 0
[05/Apr/2020 22:58:54] "GET /static/admin/fonts/Roboto-Light-webfont.woff HTTP/1.1" 304 0
[05/Apr/2020 22:58:56] "GET /admin/blog/post/ HTTP/1.1" 200 4736
[05/Apr/2020 22:58:56] "GET /admin/jsi18n/ HTTP/1.1" 200 3223
[05/Apr/2020 22:59:13] "GET /admin/blog/post/1/change/ HTTP/1.1" 200 6910
[05/Apr/2020 22:59:13] "GET /admin/jsi18n/ HTTP/1.1" 200 3223
[05/Apr/2020 22:59:17] "GET /admin/blog/post/ HTTP/1.1" 200 4736
[05/Apr/2020 22:59:17] "GET /admin/jsi18n/ HTTP/1.1" 200 3223
[05/Apr/2020 22:59:39] "GET /admin/blog/post/2/change/ HTTP/1.1" 200 6904
[05/Apr/2020 22:59:39] "GET /admin/jsi18n/ HTTP/1.1" 200 3223
[05/Apr/2020 22:59:39] "GET /static/admin/img/icon-changelink.svg HTTP/1.1" 304 0
[05/Apr/2020 22:59:39] "GET /static/admin/img/icon-addlink.svg HTTP/1.1" 304 0
[05/Apr/2020 22:59:39] "GET /static/admin/fonts/Roboto-Bold-webfont.woff HTTP/1.1" 304 0
[05/Apr/2020 22:59:45] "GET /admin/blog/post/ HTTP/1.1" 200 4736
[05/Apr/2020 22:59:45] "GET /admin/jsi18n/ HTTP/1.1" 200 3223

C:\Users\SadeedBari\Documents\djangoproject\django_project>python python manage.py startapp users
python: can't open file 'python': [Errno 2] No such file or directory

C:\Users\SadeedBari\Documents\djangoproject\django_project>python manage.py startapp users

C:\Users\SadeedBari\Documents\djangoproject\django_project>python manage.py runserver
Watching for file changes with StatReloader
Performing system checks...

System check identified no issues (0 silenced).
April 05, 2020 - 23:25:24
Django version 3.0.5, using settings 'django_project.settings'
Starting development server at http://127.0.0.1:8000/
Quit the server with CTRL-BREAK.
[05/Apr/2020 23:25:35] "GET /blog/ HTTP/1.1" 200 3812
[05/Apr/2020 23:25:35] "GET /static/blog/main.css HTTP/1.1" 304 0
[05/Apr/2020 23:25:40] "GET /register HTTP/1.1" 301 0
Internal Server Error: /register/
Traceback (most recent call last):
  File "C:\Users\SadeedBari\AppData\Local\Programs\Python\Python38-32\lib\site-packages\django\template\backends\django.py", line 61, in render
    return self.template.render(context)
  File "C:\Users\SadeedBari\AppData\Local\Programs\Python\Python38-32\lib\site-packages\django\template\base.py", line 171, in render
    return self._render(context)
  File "C:\Users\SadeedBari\AppData\Local\Programs\Python\Python38-32\lib\site-packages\django\template\base.py", line 163, in _render
    return self.nodelist.render(context)
  File "C:\Users\SadeedBari\AppData\Local\Programs\Python\Python38-32\lib\site-packages\django\template\base.py", line 936, in render
    bit = node.render_annotated(context)
  File "C:\Users\SadeedBari\AppData\Local\Programs\Python\Python38-32\lib\site-packages\django\template\base.py", line 903, in render_annotated
    return self.render(context)
  File "C:\Users\SadeedBari\AppData\Local\Programs\Python\Python38-32\lib\site-packages\django\template\loader_tags.py", line 127, in render
    compiled_parent = self.get_parent(context)
  File "C:\Users\SadeedBari\AppData\Local\Programs\Python\Python38-32\lib\site-packages\django\template\loader_tags.py", line 124, in get_parent
    return self.find_template(parent, context)
  File "C:\Users\SadeedBari\AppData\Local\Programs\Python\Python38-32\lib\site-packages\django\template\loader_tags.py", line 103, in find_template
    template, origin = context.template.engine.find_template(
  File "C:\Users\SadeedBari\AppData\Local\Programs\Python\Python38-32\lib\site-packages\django\template\engine.py", line 129, in find_template
    raise TemplateDoesNotExist(name, tried=tried)
django.template.exceptions.TemplateDoesNotExist: uers/register.html

The above exception was the direct cause of the following exception:

Traceback (most recent call last):
  File "C:\Users\SadeedBari\AppData\Local\Programs\Python\Python38-32\lib\site-packages\django\core\handlers\exception.py", line 34, in inner
    response = get_response(request)
  File "C:\Users\SadeedBari\AppData\Local\Programs\Python\Python38-32\lib\site-packages\django\core\handlers\base.py", line 115, in _get_response
    response = self.process_exception_by_middleware(e, request)
  File "C:\Users\SadeedBari\AppData\Local\Programs\Python\Python38-32\lib\site-packages\django\core\handlers\base.py", line 113, in _get_response
    response = wrapped_callback(request, *callback_args, **callback_kwargs)
  File "C:\Users\SadeedBari\Documents\djangoproject\django_project\users\views.py", line 7, in register
    return render(request, 'users/register.html', {'form': form})
  File "C:\Users\SadeedBari\AppData\Local\Programs\Python\Python38-32\lib\site-packages\django\shortcuts.py", line 19, in render
    content = loader.render_to_string(template_name, context, request, using=using)
  File "C:\Users\SadeedBari\AppData\Local\Programs\Python\Python38-32\lib\site-packages\django\template\loader.py", line 62, in render_to_string
    return template.render(context, request)
  File "C:\Users\SadeedBari\AppData\Local\Programs\Python\Python38-32\lib\site-packages\django\template\backends\django.py", line 63, in render
    reraise(exc, self.backend)
  File "C:\Users\SadeedBari\AppData\Local\Programs\Python\Python38-32\lib\site-packages\django\template\backends\django.py", line 84, in reraise
    raise new from exc
django.template.exceptions.TemplateDoesNotExist: uers/register.html
[05/Apr/2020 23:25:40] "GET /register/ HTTP/1.1" 500 123846
Not Found: /blog/register/
[05/Apr/2020 23:25:48] "GET /blog/register/ HTTP/1.1" 404 2462

C:\Users\SadeedBari\Documents\djangoproject\django_project>python manage.py runserver
Watching for file changes with StatReloader
Performing system checks...

System check identified no issues (0 silenced).
April 05, 2020 - 23:26:05
Django version 3.0.5, using settings 'django_project.settings'
Starting development server at http://127.0.0.1:8000/
Quit the server with CTRL-BREAK.
C:\Users\SadeedBari\Documents\djangoproject\django_project\django_project\urls.py changed, reloading.
Watching for file changes with StatReloader
Performing system checks...

System check identified no issues (0 silenced).
April 05, 2020 - 23:28:17
Django version 3.0.5, using settings 'django_project.settings'
Starting development server at http://127.0.0.1:8000/
Quit the server with CTRL-BREAK.
Internal Server Error: /register/
Traceback (most recent call last):
  File "C:\Users\SadeedBari\AppData\Local\Programs\Python\Python38-32\lib\site-packages\django\template\backends\django.py", line 61, in render
    return self.template.render(context)
  File "C:\Users\SadeedBari\AppData\Local\Programs\Python\Python38-32\lib\site-packages\django\template\base.py", line 171, in render
    return self._render(context)
  File "C:\Users\SadeedBari\AppData\Local\Programs\Python\Python38-32\lib\site-packages\django\template\base.py", line 163, in _render
    return self.nodelist.render(context)
  File "C:\Users\SadeedBari\AppData\Local\Programs\Python\Python38-32\lib\site-packages\django\template\base.py", line 936, in render
    bit = node.render_annotated(context)
  File "C:\Users\SadeedBari\AppData\Local\Programs\Python\Python38-32\lib\site-packages\django\template\base.py", line 903, in render_annotated
    return self.render(context)
  File "C:\Users\SadeedBari\AppData\Local\Programs\Python\Python38-32\lib\site-packages\django\template\loader_tags.py", line 127, in render
    compiled_parent = self.get_parent(context)
  File "C:\Users\SadeedBari\AppData\Local\Programs\Python\Python38-32\lib\site-packages\django\template\loader_tags.py", line 124, in get_parent
    return self.find_template(parent, context)
  File "C:\Users\SadeedBari\AppData\Local\Programs\Python\Python38-32\lib\site-packages\django\template\loader_tags.py", line 103, in find_template
    template, origin = context.template.engine.find_template(
  File "C:\Users\SadeedBari\AppData\Local\Programs\Python\Python38-32\lib\site-packages\django\template\engine.py", line 129, in find_template
    raise TemplateDoesNotExist(name, tried=tried)
django.template.exceptions.TemplateDoesNotExist: uers/register.html

The above exception was the direct cause of the following exception:

Traceback (most recent call last):
  File "C:\Users\SadeedBari\AppData\Local\Programs\Python\Python38-32\lib\site-packages\django\core\handlers\exception.py", line 34, in inner
    response = get_response(request)
  File "C:\Users\SadeedBari\AppData\Local\Programs\Python\Python38-32\lib\site-packages\django\core\handlers\base.py", line 115, in _get_response
    response = self.process_exception_by_middleware(e, request)
  File "C:\Users\SadeedBari\AppData\Local\Programs\Python\Python38-32\lib\site-packages\django\core\handlers\base.py", line 113, in _get_response
    response = wrapped_callback(request, *callback_args, **callback_kwargs)
  File "C:\Users\SadeedBari\Documents\djangoproject\django_project\users\views.py", line 7, in register
    return render(request, 'users/register.html', {'form': form})
  File "C:\Users\SadeedBari\AppData\Local\Programs\Python\Python38-32\lib\site-packages\django\shortcuts.py", line 19, in render
    content = loader.render_to_string(template_name, context, request, using=using)
  File "C:\Users\SadeedBari\AppData\Local\Programs\Python\Python38-32\lib\site-packages\django\template\loader.py", line 62, in render_to_string
    return template.render(context, request)
  File "C:\Users\SadeedBari\AppData\Local\Programs\Python\Python38-32\lib\site-packages\django\template\backends\django.py", line 63, in render
    reraise(exc, self.backend)
  File "C:\Users\SadeedBari\AppData\Local\Programs\Python\Python38-32\lib\site-packages\django\template\backends\django.py", line 84, in reraise
    raise new from exc
django.template.exceptions.TemplateDoesNotExist: uers/register.html
[05/Apr/2020 23:28:25] "GET /register/ HTTP/1.1" 500 123846
Internal Server Error: /register/
Traceback (most recent call last):
  File "C:\Users\SadeedBari\AppData\Local\Programs\Python\Python38-32\lib\site-packages\django\template\backends\django.py", line 61, in render
    return self.template.render(context)
  File "C:\Users\SadeedBari\AppData\Local\Programs\Python\Python38-32\lib\site-packages\django\template\base.py", line 171, in render
    return self._render(context)
  File "C:\Users\SadeedBari\AppData\Local\Programs\Python\Python38-32\lib\site-packages\django\template\base.py", line 163, in _render
    return self.nodelist.render(context)
  File "C:\Users\SadeedBari\AppData\Local\Programs\Python\Python38-32\lib\site-packages\django\template\base.py", line 936, in render
    bit = node.render_annotated(context)
  File "C:\Users\SadeedBari\AppData\Local\Programs\Python\Python38-32\lib\site-packages\django\template\base.py", line 903, in render_annotated
    return self.render(context)
  File "C:\Users\SadeedBari\AppData\Local\Programs\Python\Python38-32\lib\site-packages\django\template\loader_tags.py", line 127, in render
    compiled_parent = self.get_parent(context)
  File "C:\Users\SadeedBari\AppData\Local\Programs\Python\Python38-32\lib\site-packages\django\template\loader_tags.py", line 124, in get_parent
    return self.find_template(parent, context)
  File "C:\Users\SadeedBari\AppData\Local\Programs\Python\Python38-32\lib\site-packages\django\template\loader_tags.py", line 103, in find_template
    template, origin = context.template.engine.find_template(
  File "C:\Users\SadeedBari\AppData\Local\Programs\Python\Python38-32\lib\site-packages\django\template\engine.py", line 129, in find_template
    raise TemplateDoesNotExist(name, tried=tried)
django.template.exceptions.TemplateDoesNotExist: users/register.html

The above exception was the direct cause of the following exception:

Traceback (most recent call last):
  File "C:\Users\SadeedBari\AppData\Local\Programs\Python\Python38-32\lib\site-packages\django\core\handlers\exception.py", line 34, in inner
    response = get_response(request)
  File "C:\Users\SadeedBari\AppData\Local\Programs\Python\Python38-32\lib\site-packages\django\core\handlers\base.py", line 115, in _get_response
    response = self.process_exception_by_middleware(e, request)
  File "C:\Users\SadeedBari\AppData\Local\Programs\Python\Python38-32\lib\site-packages\django\core\handlers\base.py", line 113, in _get_response
    response = wrapped_callback(request, *callback_args, **callback_kwargs)
  File "C:\Users\SadeedBari\Documents\djangoproject\django_project\users\views.py", line 7, in register
    return render(request, 'users/register.html', {'form': form})
  File "C:\Users\SadeedBari\AppData\Local\Programs\Python\Python38-32\lib\site-packages\django\shortcuts.py", line 19, in render
    content = loader.render_to_string(template_name, context, request, using=using)
  File "C:\Users\SadeedBari\AppData\Local\Programs\Python\Python38-32\lib\site-packages\django\template\loader.py", line 62, in render_to_string
    return template.render(context, request)
  File "C:\Users\SadeedBari\AppData\Local\Programs\Python\Python38-32\lib\site-packages\django\template\backends\django.py", line 63, in render
    reraise(exc, self.backend)
  File "C:\Users\SadeedBari\AppData\Local\Programs\Python\Python38-32\lib\site-packages\django\template\backends\django.py", line 84, in reraise
    raise new from exc
django.template.exceptions.TemplateDoesNotExist: users/register.html
[05/Apr/2020 23:29:20] "GET /register/ HTTP/1.1" 500 123970
Internal Server Error: /register/
Traceback (most recent call last):
  File "C:\Users\SadeedBari\AppData\Local\Programs\Python\Python38-32\lib\site-packages\django\template\backends\django.py", line 61, in render
    return self.template.render(context)
  File "C:\Users\SadeedBari\AppData\Local\Programs\Python\Python38-32\lib\site-packages\django\template\base.py", line 171, in render
    return self._render(context)
  File "C:\Users\SadeedBari\AppData\Local\Programs\Python\Python38-32\lib\site-packages\django\template\base.py", line 163, in _render
    return self.nodelist.render(context)
  File "C:\Users\SadeedBari\AppData\Local\Programs\Python\Python38-32\lib\site-packages\django\template\base.py", line 936, in render
    bit = node.render_annotated(context)
  File "C:\Users\SadeedBari\AppData\Local\Programs\Python\Python38-32\lib\site-packages\django\template\base.py", line 903, in render_annotated
    return self.render(context)
  File "C:\Users\SadeedBari\AppData\Local\Programs\Python\Python38-32\lib\site-packages\django\template\loader_tags.py", line 127, in render
    compiled_parent = self.get_parent(context)
  File "C:\Users\SadeedBari\AppData\Local\Programs\Python\Python38-32\lib\site-packages\django\template\loader_tags.py", line 124, in get_parent
    return self.find_template(parent, context)
  File "C:\Users\SadeedBari\AppData\Local\Programs\Python\Python38-32\lib\site-packages\django\template\loader_tags.py", line 103, in find_template
    template, origin = context.template.engine.find_template(
  File "C:\Users\SadeedBari\AppData\Local\Programs\Python\Python38-32\lib\site-packages\django\template\engine.py", line 129, in find_template
    raise TemplateDoesNotExist(name, tried=tried)
django.template.exceptions.TemplateDoesNotExist: users/register.html

The above exception was the direct cause of the following exception:

Traceback (most recent call last):
  File "C:\Users\SadeedBari\AppData\Local\Programs\Python\Python38-32\lib\site-packages\django\core\handlers\exception.py", line 34, in inner
    response = get_response(request)
  File "C:\Users\SadeedBari\AppData\Local\Programs\Python\Python38-32\lib\site-packages\django\core\handlers\base.py", line 115, in _get_response
    response = self.process_exception_by_middleware(e, request)
  File "C:\Users\SadeedBari\AppData\Local\Programs\Python\Python38-32\lib\site-packages\django\core\handlers\base.py", line 113, in _get_response
    response = wrapped_callback(request, *callback_args, **callback_kwargs)
  File "C:\Users\SadeedBari\Documents\djangoproject\django_project\users\views.py", line 7, in register
    return render(request, 'users/register.html', {'form': form})
  File "C:\Users\SadeedBari\AppData\Local\Programs\Python\Python38-32\lib\site-packages\django\shortcuts.py", line 19, in render
    content = loader.render_to_string(template_name, context, request, using=using)
  File "C:\Users\SadeedBari\AppData\Local\Programs\Python\Python38-32\lib\site-packages\django\template\loader.py", line 62, in render_to_string
    return template.render(context, request)
  File "C:\Users\SadeedBari\AppData\Local\Programs\Python\Python38-32\lib\site-packages\django\template\backends\django.py", line 63, in render
    reraise(exc, self.backend)
  File "C:\Users\SadeedBari\AppData\Local\Programs\Python\Python38-32\lib\site-packages\django\template\backends\django.py", line 84, in reraise
    raise new from exc
django.template.exceptions.TemplateDoesNotExist: users/register.html
[05/Apr/2020 23:29:22] "GET /register/ HTTP/1.1" 500 123970

C:\Users\SadeedBari\Documents\djangoproject\django_project>python manage.py runserver
Watching for file changes with StatReloader
Performing system checks...

System check identified no issues (0 silenced).
April 05, 2020 - 23:30:03
Django version 3.0.5, using settings 'django_project.settings'
Starting development server at http://127.0.0.1:8000/
Quit the server with CTRL-BREAK.
Internal Server Error: /register/
Traceback (most recent call last):
  File "C:\Users\SadeedBari\AppData\Local\Programs\Python\Python38-32\lib\site-packages\django\template\backends\django.py", line 61, in render
    return self.template.render(context)
  File "C:\Users\SadeedBari\AppData\Local\Programs\Python\Python38-32\lib\site-packages\django\template\base.py", line 171, in render
    return self._render(context)
  File "C:\Users\SadeedBari\AppData\Local\Programs\Python\Python38-32\lib\site-packages\django\template\base.py", line 163, in _render
    return self.nodelist.render(context)
  File "C:\Users\SadeedBari\AppData\Local\Programs\Python\Python38-32\lib\site-packages\django\template\base.py", line 936, in render
    bit = node.render_annotated(context)
  File "C:\Users\SadeedBari\AppData\Local\Programs\Python\Python38-32\lib\site-packages\django\template\base.py", line 903, in render_annotated
    return self.render(context)
  File "C:\Users\SadeedBari\AppData\Local\Programs\Python\Python38-32\lib\site-packages\django\template\loader_tags.py", line 127, in render
    compiled_parent = self.get_parent(context)
  File "C:\Users\SadeedBari\AppData\Local\Programs\Python\Python38-32\lib\site-packages\django\template\loader_tags.py", line 124, in get_parent
    return self.find_template(parent, context)
  File "C:\Users\SadeedBari\AppData\Local\Programs\Python\Python38-32\lib\site-packages\django\template\loader_tags.py", line 103, in find_template
    template, origin = context.template.engine.find_template(
  File "C:\Users\SadeedBari\AppData\Local\Programs\Python\Python38-32\lib\site-packages\django\template\engine.py", line 129, in find_template
    raise TemplateDoesNotExist(name, tried=tried)
django.template.exceptions.TemplateDoesNotExist: users/register.html

The above exception was the direct cause of the following exception:

Traceback (most recent call last):
  File "C:\Users\SadeedBari\AppData\Local\Programs\Python\Python38-32\lib\site-packages\django\core\handlers\exception.py", line 34, in inner
    response = get_response(request)
  File "C:\Users\SadeedBari\AppData\Local\Programs\Python\Python38-32\lib\site-packages\django\core\handlers\base.py", line 115, in _get_response
    response = self.process_exception_by_middleware(e, request)
  File "C:\Users\SadeedBari\AppData\Local\Programs\Python\Python38-32\lib\site-packages\django\core\handlers\base.py", line 113, in _get_response
    response = wrapped_callback(request, *callback_args, **callback_kwargs)
  File "C:\Users\SadeedBari\Documents\djangoproject\django_project\users\views.py", line 7, in register
    return render(request, 'users/register.html', {'form': form})
  File "C:\Users\SadeedBari\AppData\Local\Programs\Python\Python38-32\lib\site-packages\django\shortcuts.py", line 19, in render
    content = loader.render_to_string(template_name, context, request, using=using)
  File "C:\Users\SadeedBari\AppData\Local\Programs\Python\Python38-32\lib\site-packages\django\template\loader.py", line 62, in render_to_string
    return template.render(context, request)
  File "C:\Users\SadeedBari\AppData\Local\Programs\Python\Python38-32\lib\site-packages\django\template\backends\django.py", line 63, in render
    reraise(exc, self.backend)
  File "C:\Users\SadeedBari\AppData\Local\Programs\Python\Python38-32\lib\site-packages\django\template\backends\django.py", line 84, in reraise
    raise new from exc
django.template.exceptions.TemplateDoesNotExist: users/register.html
[05/Apr/2020 23:30:07] "GET /register/ HTTP/1.1" 500 123970
[05/Apr/2020 23:30:11] "GET /blog/ HTTP/1.1" 200 3812
Internal Server Error: /register/
Traceback (most recent call last):
  File "C:\Users\SadeedBari\AppData\Local\Programs\Python\Python38-32\lib\site-packages\django\template\backends\django.py", line 61, in render
    return self.template.render(context)
  File "C:\Users\SadeedBari\AppData\Local\Programs\Python\Python38-32\lib\site-packages\django\template\base.py", line 171, in render
    return self._render(context)
  File "C:\Users\SadeedBari\AppData\Local\Programs\Python\Python38-32\lib\site-packages\django\template\base.py", line 163, in _render
    return self.nodelist.render(context)
  File "C:\Users\SadeedBari\AppData\Local\Programs\Python\Python38-32\lib\site-packages\django\template\base.py", line 936, in render
    bit = node.render_annotated(context)
  File "C:\Users\SadeedBari\AppData\Local\Programs\Python\Python38-32\lib\site-packages\django\template\base.py", line 903, in render_annotated
    return self.render(context)
  File "C:\Users\SadeedBari\AppData\Local\Programs\Python\Python38-32\lib\site-packages\django\template\loader_tags.py", line 127, in render
    compiled_parent = self.get_parent(context)
  File "C:\Users\SadeedBari\AppData\Local\Programs\Python\Python38-32\lib\site-packages\django\template\loader_tags.py", line 124, in get_parent
    return self.find_template(parent, context)
  File "C:\Users\SadeedBari\AppData\Local\Programs\Python\Python38-32\lib\site-packages\django\template\loader_tags.py", line 103, in find_template
    template, origin = context.template.engine.find_template(
  File "C:\Users\SadeedBari\AppData\Local\Programs\Python\Python38-32\lib\site-packages\django\template\engine.py", line 129, in find_template
    raise TemplateDoesNotExist(name, tried=tried)
django.template.exceptions.TemplateDoesNotExist: users/register.html

The above exception was the direct cause of the following exception:

Traceback (most recent call last):
  File "C:\Users\SadeedBari\AppData\Local\Programs\Python\Python38-32\lib\site-packages\django\core\handlers\exception.py", line 34, in inner
    response = get_response(request)
  File "C:\Users\SadeedBari\AppData\Local\Programs\Python\Python38-32\lib\site-packages\django\core\handlers\base.py", line 115, in _get_response
    response = self.process_exception_by_middleware(e, request)
  File "C:\Users\SadeedBari\AppData\Local\Programs\Python\Python38-32\lib\site-packages\django\core\handlers\base.py", line 113, in _get_response
    response = wrapped_callback(request, *callback_args, **callback_kwargs)
  File "C:\Users\SadeedBari\Documents\djangoproject\django_project\users\views.py", line 7, in register
    return render(request, 'users/register.html', {'form': form})
  File "C:\Users\SadeedBari\AppData\Local\Programs\Python\Python38-32\lib\site-packages\django\shortcuts.py", line 19, in render
    content = loader.render_to_string(template_name, context, request, using=using)
  File "C:\Users\SadeedBari\AppData\Local\Programs\Python\Python38-32\lib\site-packages\django\template\loader.py", line 62, in render_to_string
    return template.render(context, request)
  File "C:\Users\SadeedBari\AppData\Local\Programs\Python\Python38-32\lib\site-packages\django\template\backends\django.py", line 63, in render
    reraise(exc, self.backend)
  File "C:\Users\SadeedBari\AppData\Local\Programs\Python\Python38-32\lib\site-packages\django\template\backends\django.py", line 84, in reraise
    raise new from exc
django.template.exceptions.TemplateDoesNotExist: users/register.html
[05/Apr/2020 23:30:16] "GET /register/ HTTP/1.1" 500 123833
[05/Apr/2020 23:31:34] "GET /register/ HTTP/1.1" 200 4348
[05/Apr/2020 23:33:48] "GET /register/ HTTP/1.1" 200 4282
[05/Apr/2020 23:42:44] "POST /register/ HTTP/1.1" 200 4282
[05/Apr/2020 23:42:44] "GET /static/blog/main.css HTTP/1.1" 304 0
[05/Apr/2020 23:44:16] "POST /register/ HTTP/1.1" 200 4282
C:\Users\SadeedBari\Documents\djangoproject\django_project\users\views.py changed, reloading.
Watching for file changes with StatReloader
Performing system checks...

System check identified no issues (0 silenced).
April 05, 2020 - 23:45:18
Django version 3.0.5, using settings 'django_project.settings'
Starting development server at http://127.0.0.1:8000/
Quit the server with CTRL-BREAK.
C:\Users\SadeedBari\Documents\djangoproject\django_project\users\views.py changed, reloading.
Watching for file changes with StatReloader
Performing system checks...

Exception in thread django-main-thread:
Traceback (most recent call last):
  File "C:\Users\SadeedBari\AppData\Local\Programs\Python\Python38-32\lib\threading.py", line 932, in _bootstrap_inner
    self.run()
  File "C:\Users\SadeedBari\AppData\Local\Programs\Python\Python38-32\lib\threading.py", line 870, in run
    self._target(*self._args, **self._kwargs)
  File "C:\Users\SadeedBari\AppData\Local\Programs\Python\Python38-32\lib\site-packages\django\utils\autoreload.py", line 53, in wrapper
    fn(*args, **kwargs)
  File "C:\Users\SadeedBari\AppData\Local\Programs\Python\Python38-32\lib\site-packages\django\core\management\commands\runserver.py", line 117, in inner_run
    self.check(display_num_errors=True)
  File "C:\Users\SadeedBari\AppData\Local\Programs\Python\Python38-32\lib\site-packages\django\core\management\base.py", line 392, in check
    all_issues = self._run_checks(
  File "C:\Users\SadeedBari\AppData\Local\Programs\Python\Python38-32\lib\site-packages\django\core\management\base.py", line 382, in _run_checks
    return checks.run_checks(**kwargs)
  File "C:\Users\SadeedBari\AppData\Local\Programs\Python\Python38-32\lib\site-packages\django\core\checks\registry.py", line 72, in run_checks
    new_errors = check(app_configs=app_configs)
  File "C:\Users\SadeedBari\AppData\Local\Programs\Python\Python38-32\lib\site-packages\django\core\checks\urls.py", line 13, in check_url_config
    return check_resolver(resolver)
  File "C:\Users\SadeedBari\AppData\Local\Programs\Python\Python38-32\lib\site-packages\django\core\checks\urls.py", line 23, in check_resolver
    return check_method()
  File "C:\Users\SadeedBari\AppData\Local\Programs\Python\Python38-32\lib\site-packages\django\urls\resolvers.py", line 407, in check
    for pattern in self.url_patterns:
  File "C:\Users\SadeedBari\AppData\Local\Programs\Python\Python38-32\lib\site-packages\django\utils\functional.py", line 48, in __get__
    res = instance.__dict__[self.name] = self.func(instance)
  File "C:\Users\SadeedBari\AppData\Local\Programs\Python\Python38-32\lib\site-packages\django\urls\resolvers.py", line 588, in url_patterns
    patterns = getattr(self.urlconf_module, "urlpatterns", self.urlconf_module)
  File "C:\Users\SadeedBari\AppData\Local\Programs\Python\Python38-32\lib\site-packages\django\utils\functional.py", line 48, in __get__
    res = instance.__dict__[self.name] = self.func(instance)
  File "C:\Users\SadeedBari\AppData\Local\Programs\Python\Python38-32\lib\site-packages\django\urls\resolvers.py", line 581, in urlconf_module
    return import_module(self.urlconf_name)
  File "C:\Users\SadeedBari\AppData\Local\Programs\Python\Python38-32\lib\importlib\__init__.py", line 127, in import_module
    return _bootstrap._gcd_import(name[level:], package, level)
  File "<frozen importlib._bootstrap>", line 1014, in _gcd_import
  File "<frozen importlib._bootstrap>", line 991, in _find_and_load
  File "<frozen importlib._bootstrap>", line 975, in _find_and_load_unlocked
  File "<frozen importlib._bootstrap>", line 671, in _load_unlocked
  File "<frozen importlib._bootstrap_external>", line 783, in exec_module
  File "<frozen importlib._bootstrap>", line 219, in _call_with_frames_removed
  File "C:\Users\SadeedBari\Documents\djangoproject\django_project\django_project\urls.py", line 18, in <module>
    from users import views as user_views
  File "C:\Users\SadeedBari\Documents\djangoproject\django_project\users\views.py", line 9
    if form.is_valid)_"
    ^
IndentationError: unexpected indent
C:\Users\SadeedBari\Documents\djangoproject\django_project\users\views.py changed, reloading.
Watching for file changes with StatReloader
Performing system checks...

Exception in thread django-main-thread:
Traceback (most recent call last):
  File "C:\Users\SadeedBari\AppData\Local\Programs\Python\Python38-32\lib\threading.py", line 932, in _bootstrap_inner
    self.run()
  File "C:\Users\SadeedBari\AppData\Local\Programs\Python\Python38-32\lib\threading.py", line 870, in run
    self._target(*self._args, **self._kwargs)
  File "C:\Users\SadeedBari\AppData\Local\Programs\Python\Python38-32\lib\site-packages\django\utils\autoreload.py", line 53, in wrapper
    fn(*args, **kwargs)
  File "C:\Users\SadeedBari\AppData\Local\Programs\Python\Python38-32\lib\site-packages\django\core\management\commands\runserver.py", line 117, in inner_run
    self.check(display_num_errors=True)
  File "C:\Users\SadeedBari\AppData\Local\Programs\Python\Python38-32\lib\site-packages\django\core\management\base.py", line 392, in check
    all_issues = self._run_checks(
  File "C:\Users\SadeedBari\AppData\Local\Programs\Python\Python38-32\lib\site-packages\django\core\management\base.py", line 382, in _run_checks
    return checks.run_checks(**kwargs)
  File "C:\Users\SadeedBari\AppData\Local\Programs\Python\Python38-32\lib\site-packages\django\core\checks\registry.py", line 72, in run_checks
    new_errors = check(app_configs=app_configs)
  File "C:\Users\SadeedBari\AppData\Local\Programs\Python\Python38-32\lib\site-packages\django\core\checks\urls.py", line 13, in check_url_config
    return check_resolver(resolver)
  File "C:\Users\SadeedBari\AppData\Local\Programs\Python\Python38-32\lib\site-packages\django\core\checks\urls.py", line 23, in check_resolver
    return check_method()
  File "C:\Users\SadeedBari\AppData\Local\Programs\Python\Python38-32\lib\site-packages\django\urls\resolvers.py", line 407, in check
    for pattern in self.url_patterns:
  File "C:\Users\SadeedBari\AppData\Local\Programs\Python\Python38-32\lib\site-packages\django\utils\functional.py", line 48, in __get__
    res = instance.__dict__[self.name] = self.func(instance)
  File "C:\Users\SadeedBari\AppData\Local\Programs\Python\Python38-32\lib\site-packages\django\urls\resolvers.py", line 588, in url_patterns
    patterns = getattr(self.urlconf_module, "urlpatterns", self.urlconf_module)
  File "C:\Users\SadeedBari\AppData\Local\Programs\Python\Python38-32\lib\site-packages\django\utils\functional.py", line 48, in __get__
    res = instance.__dict__[self.name] = self.func(instance)
  File "C:\Users\SadeedBari\AppData\Local\Programs\Python\Python38-32\lib\site-packages\django\urls\resolvers.py", line 581, in urlconf_module
    return import_module(self.urlconf_name)
  File "C:\Users\SadeedBari\AppData\Local\Programs\Python\Python38-32\lib\importlib\__init__.py", line 127, in import_module
    return _bootstrap._gcd_import(name[level:], package, level)
  File "<frozen importlib._bootstrap>", line 1014, in _gcd_import
  File "<frozen importlib._bootstrap>", line 991, in _find_and_load
  File "<frozen importlib._bootstrap>", line 975, in _find_and_load_unlocked
  File "<frozen importlib._bootstrap>", line 671, in _load_unlocked
  File "<frozen importlib._bootstrap_external>", line 783, in exec_module
  File "<frozen importlib._bootstrap>", line 219, in _call_with_frames_removed
  File "C:\Users\SadeedBari\Documents\djangoproject\django_project\django_project\urls.py", line 18, in <module>
    from users import views as user_views
  File "C:\Users\SadeedBari\Documents\djangoproject\django_project\users\views.py", line 9
    if form.is_valid)_"
    ^
IndentationError: unexpected indent
C:\Users\SadeedBari\Documents\djangoproject\django_project\users\views.py changed, reloading.
Watching for file changes with StatReloader
Performing system checks...

Exception in thread django-main-thread:
Traceback (most recent call last):
  File "C:\Users\SadeedBari\AppData\Local\Programs\Python\Python38-32\lib\threading.py", line 932, in _bootstrap_inner
    self.run()
  File "C:\Users\SadeedBari\AppData\Local\Programs\Python\Python38-32\lib\threading.py", line 870, in run
    self._target(*self._args, **self._kwargs)
  File "C:\Users\SadeedBari\AppData\Local\Programs\Python\Python38-32\lib\site-packages\django\utils\autoreload.py", line 53, in wrapper
    fn(*args, **kwargs)
  File "C:\Users\SadeedBari\AppData\Local\Programs\Python\Python38-32\lib\site-packages\django\core\management\commands\runserver.py", line 117, in inner_run
    self.check(display_num_errors=True)
  File "C:\Users\SadeedBari\AppData\Local\Programs\Python\Python38-32\lib\site-packages\django\core\management\base.py", line 392, in check
    all_issues = self._run_checks(
  File "C:\Users\SadeedBari\AppData\Local\Programs\Python\Python38-32\lib\site-packages\django\core\management\base.py", line 382, in _run_checks
    return checks.run_checks(**kwargs)
  File "C:\Users\SadeedBari\AppData\Local\Programs\Python\Python38-32\lib\site-packages\django\core\checks\registry.py", line 72, in run_checks
    new_errors = check(app_configs=app_configs)
  File "C:\Users\SadeedBari\AppData\Local\Programs\Python\Python38-32\lib\site-packages\django\core\checks\urls.py", line 13, in check_url_config
    return check_resolver(resolver)
  File "C:\Users\SadeedBari\AppData\Local\Programs\Python\Python38-32\lib\site-packages\django\core\checks\urls.py", line 23, in check_resolver
    return check_method()
  File "C:\Users\SadeedBari\AppData\Local\Programs\Python\Python38-32\lib\site-packages\django\urls\resolvers.py", line 407, in check
    for pattern in self.url_patterns:
  File "C:\Users\SadeedBari\AppData\Local\Programs\Python\Python38-32\lib\site-packages\django\utils\functional.py", line 48, in __get__
    res = instance.__dict__[self.name] = self.func(instance)
  File "C:\Users\SadeedBari\AppData\Local\Programs\Python\Python38-32\lib\site-packages\django\urls\resolvers.py", line 588, in url_patterns
    patterns = getattr(self.urlconf_module, "urlpatterns", self.urlconf_module)
  File "C:\Users\SadeedBari\AppData\Local\Programs\Python\Python38-32\lib\site-packages\django\utils\functional.py", line 48, in __get__
    res = instance.__dict__[self.name] = self.func(instance)
  File "C:\Users\SadeedBari\AppData\Local\Programs\Python\Python38-32\lib\site-packages\django\urls\resolvers.py", line 581, in urlconf_module
    return import_module(self.urlconf_name)
  File "C:\Users\SadeedBari\AppData\Local\Programs\Python\Python38-32\lib\importlib\__init__.py", line 127, in import_module
    return _bootstrap._gcd_import(name[level:], package, level)
  File "<frozen importlib._bootstrap>", line 1014, in _gcd_import
  File "<frozen importlib._bootstrap>", line 991, in _find_and_load
  File "<frozen importlib._bootstrap>", line 975, in _find_and_load_unlocked
  File "<frozen importlib._bootstrap>", line 671, in _load_unlocked
  File "<frozen importlib._bootstrap_external>", line 783, in exec_module
  File "<frozen importlib._bootstrap>", line 219, in _call_with_frames_removed
  File "C:\Users\SadeedBari\Documents\djangoproject\django_project\django_project\urls.py", line 18, in <module>
    from users import views as user_views
  File "C:\Users\SadeedBari\Documents\djangoproject\django_project\users\views.py", line 9
    if form.is_valid)_"
    ^
IndentationError: unexpected indent
C:\Users\SadeedBari\Documents\djangoproject\django_project\users\views.py changed, reloading.
Watching for file changes with StatReloader
Performing system checks...

Exception in thread django-main-thread:
Traceback (most recent call last):
  File "C:\Users\SadeedBari\AppData\Local\Programs\Python\Python38-32\lib\threading.py", line 932, in _bootstrap_inner
    self.run()
  File "C:\Users\SadeedBari\AppData\Local\Programs\Python\Python38-32\lib\threading.py", line 870, in run
    self._target(*self._args, **self._kwargs)
  File "C:\Users\SadeedBari\AppData\Local\Programs\Python\Python38-32\lib\site-packages\django\utils\autoreload.py", line 53, in wrapper
    fn(*args, **kwargs)
  File "C:\Users\SadeedBari\AppData\Local\Programs\Python\Python38-32\lib\site-packages\django\core\management\commands\runserver.py", line 117, in inner_run
    self.check(display_num_errors=True)
  File "C:\Users\SadeedBari\AppData\Local\Programs\Python\Python38-32\lib\site-packages\django\core\management\base.py", line 392, in check
    all_issues = self._run_checks(
  File "C:\Users\SadeedBari\AppData\Local\Programs\Python\Python38-32\lib\site-packages\django\core\management\base.py", line 382, in _run_checks
    return checks.run_checks(**kwargs)
  File "C:\Users\SadeedBari\AppData\Local\Programs\Python\Python38-32\lib\site-packages\django\core\checks\registry.py", line 72, in run_checks
    new_errors = check(app_configs=app_configs)
  File "C:\Users\SadeedBari\AppData\Local\Programs\Python\Python38-32\lib\site-packages\django\core\checks\urls.py", line 13, in check_url_config
    return check_resolver(resolver)
  File "C:\Users\SadeedBari\AppData\Local\Programs\Python\Python38-32\lib\site-packages\django\core\checks\urls.py", line 23, in check_resolver
    return check_method()
  File "C:\Users\SadeedBari\AppData\Local\Programs\Python\Python38-32\lib\site-packages\django\urls\resolvers.py", line 407, in check
    for pattern in self.url_patterns:
  File "C:\Users\SadeedBari\AppData\Local\Programs\Python\Python38-32\lib\site-packages\django\utils\functional.py", line 48, in __get__
    res = instance.__dict__[self.name] = self.func(instance)
  File "C:\Users\SadeedBari\AppData\Local\Programs\Python\Python38-32\lib\site-packages\django\urls\resolvers.py", line 588, in url_patterns
    patterns = getattr(self.urlconf_module, "urlpatterns", self.urlconf_module)
  File "C:\Users\SadeedBari\AppData\Local\Programs\Python\Python38-32\lib\site-packages\django\utils\functional.py", line 48, in __get__
    res = instance.__dict__[self.name] = self.func(instance)
  File "C:\Users\SadeedBari\AppData\Local\Programs\Python\Python38-32\lib\site-packages\django\urls\resolvers.py", line 581, in urlconf_module
    return import_module(self.urlconf_name)
  File "C:\Users\SadeedBari\AppData\Local\Programs\Python\Python38-32\lib\importlib\__init__.py", line 127, in import_module
    return _bootstrap._gcd_import(name[level:], package, level)
  File "<frozen importlib._bootstrap>", line 1014, in _gcd_import
  File "<frozen importlib._bootstrap>", line 991, in _find_and_load
  File "<frozen importlib._bootstrap>", line 975, in _find_and_load_unlocked
  File "<frozen importlib._bootstrap>", line 671, in _load_unlocked
  File "<frozen importlib._bootstrap_external>", line 783, in exec_module
  File "<frozen importlib._bootstrap>", line 219, in _call_with_frames_removed
  File "C:\Users\SadeedBari\Documents\djangoproject\django_project\django_project\urls.py", line 18, in <module>
    from users import views as user_views
  File "C:\Users\SadeedBari\Documents\djangoproject\django_project\users\views.py", line 9
    if form.is_valid)_"
    ^
IndentationError: unexpected indent

C:\Users\SadeedBari\Documents\djangoproject\django_project>python manage.py runserver
Watching for file changes with StatReloader
Performing system checks...

Exception in thread django-main-thread:
Traceback (most recent call last):
  File "C:\Users\SadeedBari\AppData\Local\Programs\Python\Python38-32\lib\threading.py", line 932, in _bootstrap_inner
    self.run()
  File "C:\Users\SadeedBari\AppData\Local\Programs\Python\Python38-32\lib\threading.py", line 870, in run
    self._target(*self._args, **self._kwargs)
  File "C:\Users\SadeedBari\AppData\Local\Programs\Python\Python38-32\lib\site-packages\django\utils\autoreload.py", line 53, in wrapper
    fn(*args, **kwargs)
  File "C:\Users\SadeedBari\AppData\Local\Programs\Python\Python38-32\lib\site-packages\django\core\management\commands\runserver.py", line 117, in inner_run
    self.check(display_num_errors=True)
  File "C:\Users\SadeedBari\AppData\Local\Programs\Python\Python38-32\lib\site-packages\django\core\management\base.py", line 392, in check
    all_issues = self._run_checks(
  File "C:\Users\SadeedBari\AppData\Local\Programs\Python\Python38-32\lib\site-packages\django\core\management\base.py", line 382, in _run_checks
    return checks.run_checks(**kwargs)
  File "C:\Users\SadeedBari\AppData\Local\Programs\Python\Python38-32\lib\site-packages\django\core\checks\registry.py", line 72, in run_checks
    new_errors = check(app_configs=app_configs)
  File "C:\Users\SadeedBari\AppData\Local\Programs\Python\Python38-32\lib\site-packages\django\core\checks\urls.py", line 13, in check_url_config
    return check_resolver(resolver)
  File "C:\Users\SadeedBari\AppData\Local\Programs\Python\Python38-32\lib\site-packages\django\core\checks\urls.py", line 23, in check_resolver
    return check_method()
  File "C:\Users\SadeedBari\AppData\Local\Programs\Python\Python38-32\lib\site-packages\django\urls\resolvers.py", line 407, in check
    for pattern in self.url_patterns:
  File "C:\Users\SadeedBari\AppData\Local\Programs\Python\Python38-32\lib\site-packages\django\utils\functional.py", line 48, in __get__
    res = instance.__dict__[self.name] = self.func(instance)
  File "C:\Users\SadeedBari\AppData\Local\Programs\Python\Python38-32\lib\site-packages\django\urls\resolvers.py", line 588, in url_patterns
    patterns = getattr(self.urlconf_module, "urlpatterns", self.urlconf_module)
  File "C:\Users\SadeedBari\AppData\Local\Programs\Python\Python38-32\lib\site-packages\django\utils\functional.py", line 48, in __get__
    res = instance.__dict__[self.name] = self.func(instance)
  File "C:\Users\SadeedBari\AppData\Local\Programs\Python\Python38-32\lib\site-packages\django\urls\resolvers.py", line 581, in urlconf_module
    return import_module(self.urlconf_name)
  File "C:\Users\SadeedBari\AppData\Local\Programs\Python\Python38-32\lib\importlib\__init__.py", line 127, in import_module
    return _bootstrap._gcd_import(name[level:], package, level)
  File "<frozen importlib._bootstrap>", line 1014, in _gcd_import
  File "<frozen importlib._bootstrap>", line 991, in _find_and_load
  File "<frozen importlib._bootstrap>", line 975, in _find_and_load_unlocked
  File "<frozen importlib._bootstrap>", line 671, in _load_unlocked
  File "<frozen importlib._bootstrap_external>", line 783, in exec_module
  File "<frozen importlib._bootstrap>", line 219, in _call_with_frames_removed
  File "C:\Users\SadeedBari\Documents\djangoproject\django_project\django_project\urls.py", line 18, in <module>
    from users import views as user_views
  File "C:\Users\SadeedBari\Documents\djangoproject\django_project\users\views.py", line 9
    if form.is_valid)_"
    ^
IndentationError: unexpected indent
C:\Users\SadeedBari\Documents\djangoproject\django_project\users\views.py changed, reloading.
Watching for file changes with StatReloader
Performing system checks...

Exception in thread django-main-thread:
Traceback (most recent call last):
  File "C:\Users\SadeedBari\AppData\Local\Programs\Python\Python38-32\lib\threading.py", line 932, in _bootstrap_inner
    self.run()
  File "C:\Users\SadeedBari\AppData\Local\Programs\Python\Python38-32\lib\threading.py", line 870, in run
    self._target(*self._args, **self._kwargs)
  File "C:\Users\SadeedBari\AppData\Local\Programs\Python\Python38-32\lib\site-packages\django\utils\autoreload.py", line 53, in wrapper
    fn(*args, **kwargs)
  File "C:\Users\SadeedBari\AppData\Local\Programs\Python\Python38-32\lib\site-packages\django\core\management\commands\runserver.py", line 117, in inner_run
    self.check(display_num_errors=True)
  File "C:\Users\SadeedBari\AppData\Local\Programs\Python\Python38-32\lib\site-packages\django\core\management\base.py", line 392, in check
    all_issues = self._run_checks(
  File "C:\Users\SadeedBari\AppData\Local\Programs\Python\Python38-32\lib\site-packages\django\core\management\base.py", line 382, in _run_checks
    return checks.run_checks(**kwargs)
  File "C:\Users\SadeedBari\AppData\Local\Programs\Python\Python38-32\lib\site-packages\django\core\checks\registry.py", line 72, in run_checks
    new_errors = check(app_configs=app_configs)
  File "C:\Users\SadeedBari\AppData\Local\Programs\Python\Python38-32\lib\site-packages\django\core\checks\urls.py", line 13, in check_url_config
    return check_resolver(resolver)
  File "C:\Users\SadeedBari\AppData\Local\Programs\Python\Python38-32\lib\site-packages\django\core\checks\urls.py", line 23, in check_resolver
    return check_method()
  File "C:\Users\SadeedBari\AppData\Local\Programs\Python\Python38-32\lib\site-packages\django\urls\resolvers.py", line 407, in check
    for pattern in self.url_patterns:
  File "C:\Users\SadeedBari\AppData\Local\Programs\Python\Python38-32\lib\site-packages\django\utils\functional.py", line 48, in __get__
    res = instance.__dict__[self.name] = self.func(instance)
  File "C:\Users\SadeedBari\AppData\Local\Programs\Python\Python38-32\lib\site-packages\django\urls\resolvers.py", line 588, in url_patterns
    patterns = getattr(self.urlconf_module, "urlpatterns", self.urlconf_module)
  File "C:\Users\SadeedBari\AppData\Local\Programs\Python\Python38-32\lib\site-packages\django\utils\functional.py", line 48, in __get__
    res = instance.__dict__[self.name] = self.func(instance)
  File "C:\Users\SadeedBari\AppData\Local\Programs\Python\Python38-32\lib\site-packages\django\urls\resolvers.py", line 581, in urlconf_module
    return import_module(self.urlconf_name)
  File "C:\Users\SadeedBari\AppData\Local\Programs\Python\Python38-32\lib\importlib\__init__.py", line 127, in import_module
    return _bootstrap._gcd_import(name[level:], package, level)
  File "<frozen importlib._bootstrap>", line 1014, in _gcd_import
  File "<frozen importlib._bootstrap>", line 991, in _find_and_load
  File "<frozen importlib._bootstrap>", line 975, in _find_and_load_unlocked
  File "<frozen importlib._bootstrap>", line 671, in _load_unlocked
  File "<frozen importlib._bootstrap_external>", line 783, in exec_module
  File "<frozen importlib._bootstrap>", line 219, in _call_with_frames_removed
  File "C:\Users\SadeedBari\Documents\djangoproject\django_project\django_project\urls.py", line 18, in <module>
    from users import views as user_views
  File "C:\Users\SadeedBari\Documents\djangoproject\django_project\users\views.py", line 9
    if (form.is_valid):
    ^
IndentationError: unexpected indent
C:\Users\SadeedBari\Documents\djangoproject\django_project\users\views.py changed, reloading.
Watching for file changes with StatReloader
Performing system checks...

Exception in thread django-main-thread:
Traceback (most recent call last):
  File "C:\Users\SadeedBari\AppData\Local\Programs\Python\Python38-32\lib\threading.py", line 932, in _bootstrap_inner
    self.run()
  File "C:\Users\SadeedBari\AppData\Local\Programs\Python\Python38-32\lib\threading.py", line 870, in run
    self._target(*self._args, **self._kwargs)
  File "C:\Users\SadeedBari\AppData\Local\Programs\Python\Python38-32\lib\site-packages\django\utils\autoreload.py", line 53, in wrapper
    fn(*args, **kwargs)
  File "C:\Users\SadeedBari\AppData\Local\Programs\Python\Python38-32\lib\site-packages\django\core\management\commands\runserver.py", line 117, in inner_run
    self.check(display_num_errors=True)
  File "C:\Users\SadeedBari\AppData\Local\Programs\Python\Python38-32\lib\site-packages\django\core\management\base.py", line 392, in check
    all_issues = self._run_checks(
  File "C:\Users\SadeedBari\AppData\Local\Programs\Python\Python38-32\lib\site-packages\django\core\management\base.py", line 382, in _run_checks
    return checks.run_checks(**kwargs)
  File "C:\Users\SadeedBari\AppData\Local\Programs\Python\Python38-32\lib\site-packages\django\core\checks\registry.py", line 72, in run_checks
    new_errors = check(app_configs=app_configs)
  File "C:\Users\SadeedBari\AppData\Local\Programs\Python\Python38-32\lib\site-packages\django\core\checks\urls.py", line 13, in check_url_config
    return check_resolver(resolver)
  File "C:\Users\SadeedBari\AppData\Local\Programs\Python\Python38-32\lib\site-packages\django\core\checks\urls.py", line 23, in check_resolver
    return check_method()
  File "C:\Users\SadeedBari\AppData\Local\Programs\Python\Python38-32\lib\site-packages\django\urls\resolvers.py", line 407, in check
    for pattern in self.url_patterns:
  File "C:\Users\SadeedBari\AppData\Local\Programs\Python\Python38-32\lib\site-packages\django\utils\functional.py", line 48, in __get__
    res = instance.__dict__[self.name] = self.func(instance)
  File "C:\Users\SadeedBari\AppData\Local\Programs\Python\Python38-32\lib\site-packages\django\urls\resolvers.py", line 588, in url_patterns
    patterns = getattr(self.urlconf_module, "urlpatterns", self.urlconf_module)
  File "C:\Users\SadeedBari\AppData\Local\Programs\Python\Python38-32\lib\site-packages\django\utils\functional.py", line 48, in __get__
    res = instance.__dict__[self.name] = self.func(instance)
  File "C:\Users\SadeedBari\AppData\Local\Programs\Python\Python38-32\lib\site-packages\django\urls\resolvers.py", line 581, in urlconf_module
    return import_module(self.urlconf_name)
  File "C:\Users\SadeedBari\AppData\Local\Programs\Python\Python38-32\lib\importlib\__init__.py", line 127, in import_module
    return _bootstrap._gcd_import(name[level:], package, level)
  File "<frozen importlib._bootstrap>", line 1014, in _gcd_import
  File "<frozen importlib._bootstrap>", line 991, in _find_and_load
  File "<frozen importlib._bootstrap>", line 975, in _find_and_load_unlocked
  File "<frozen importlib._bootstrap>", line 671, in _load_unlocked
  File "<frozen importlib._bootstrap_external>", line 783, in exec_module
  File "<frozen importlib._bootstrap>", line 219, in _call_with_frames_removed
  File "C:\Users\SadeedBari\Documents\djangoproject\django_project\django_project\urls.py", line 18, in <module>
    from users import views as user_views
  File "C:\Users\SadeedBari\Documents\djangoproject\django_project\users\views.py", line 9
    if form.is_valid:
    ^
IndentationError: unexpected indent
C:\Users\SadeedBari\Documents\djangoproject\django_project\users\views.py changed, reloading.
Watching for file changes with StatReloader
Performing system checks...

System check identified no issues (0 silenced).
April 06, 2020 - 00:09:59
Django version 3.0.5, using settings 'django_project.settings'
Starting development server at http://127.0.0.1:8000/
Quit the server with CTRL-BREAK.
Not Found: /
[06/Apr/2020 00:10:06] "GET / HTTP/1.1" 404 2160
Not Found: /
[06/Apr/2020 00:10:08] "GET / HTTP/1.1" 404 2160
[06/Apr/2020 00:10:14] "GET /blog/ HTTP/1.1" 200 3816
[06/Apr/2020 00:10:14] "GET /static/blog/main.css HTTP/1.1" 304 0
[06/Apr/2020 00:10:18] "GET /register/ HTTP/1.1" 200 4286
Internal Server Error: /register/
Traceback (most recent call last):
  File "C:\Users\SadeedBari\AppData\Local\Programs\Python\Python38-32\lib\site-packages\django\core\handlers\exception.py", line 34, in inner
    response = get_response(request)
  File "C:\Users\SadeedBari\AppData\Local\Programs\Python\Python38-32\lib\site-packages\django\core\handlers\base.py", line 115, in _get_response
    response = self.process_exception_by_middleware(e, request)
  File "C:\Users\SadeedBari\AppData\Local\Programs\Python\Python38-32\lib\site-packages\django\core\handlers\base.py", line 113, in _get_response
    response = wrapped_callback(request, *callback_args, **callback_kwargs)
  File "C:\Users\SadeedBari\Documents\djangoproject\django_project\users\views.py", line 10, in register
    username = form.cleaned_data.get('username')
AttributeError: 'UserCreationForm' object has no attribute 'cleaned_data'
[06/Apr/2020 00:10:50] "POST /register/ HTTP/1.1" 500 67588
C:\Users\SadeedBari\Documents\djangoproject\django_project\users\views.py changed, reloading.
Watching for file changes with StatReloader
Performing system checks...

System check identified no issues (0 silenced).
April 06, 2020 - 00:12:45
Django version 3.0.5, using settings 'django_project.settings'
Starting development server at http://127.0.0.1:8000/
Quit the server with CTRL-BREAK.
[06/Apr/2020 00:12:52] "GET /register/ HTTP/1.1" 200 4286
Internal Server Error: /register/
Traceback (most recent call last):
  File "C:\Users\SadeedBari\AppData\Local\Programs\Python\Python38-32\lib\site-packages\django\core\handlers\exception.py", line 34, in inner
    response = get_response(request)
  File "C:\Users\SadeedBari\AppData\Local\Programs\Python\Python38-32\lib\site-packages\django\core\handlers\base.py", line 115, in _get_response
    response = self.process_exception_by_middleware(e, request)
  File "C:\Users\SadeedBari\AppData\Local\Programs\Python\Python38-32\lib\site-packages\django\core\handlers\base.py", line 113, in _get_response
    response = wrapped_callback(request, *callback_args, **callback_kwargs)
  File "C:\Users\SadeedBari\Documents\djangoproject\django_project\users\views.py", line 11, in register
    username = form.cleaned_data.get('username')
AttributeError: 'UserCreationForm' object has no attribute 'cleaned_data'
[06/Apr/2020 00:13:02] "POST /register/ HTTP/1.1" 500 67575
C:\Users\SadeedBari\Documents\djangoproject\django_project\users\views.py changed, reloading.
Watching for file changes with StatReloader
Performing system checks...

System check identified no issues (0 silenced).
April 06, 2020 - 00:14:37
Django version 3.0.5, using settings 'django_project.settings'
Starting development server at http://127.0.0.1:8000/
Quit the server with CTRL-BREAK.
[06/Apr/2020 00:14:40] "GET /register/ HTTP/1.1" 200 4286
[06/Apr/2020 00:14:52] "POST /register/ HTTP/1.1" 302 0
[06/Apr/2020 00:14:52] "GET /blog/ HTTP/1.1" 200 3917
[06/Apr/2020 00:33:37] "GET /blog/ HTTP/1.1" 200 3816
[06/Apr/2020 00:33:37] "GET /static/blog/main.css HTTP/1.1" 304 0
[06/Apr/2020 00:33:40] "GET /register/ HTTP/1.1" 200 4286
[06/Apr/2020 00:33:49] "GET /register/ HTTP/1.1" 200 4286
[06/Apr/2020 00:33:59] "POST /register/ HTTP/1.1" 200 4459
C:\Users\SadeedBari\Documents\djangoproject\django_project\users\views.py changed, reloading.
Watching for file changes with StatReloader
Performing system checks...

System check identified no issues (0 silenced).
April 06, 2020 - 00:40:27
Django version 3.0.5, using settings 'django_project.settings'
Starting development server at http://127.0.0.1:8000/
Quit the server with CTRL-BREAK.
C:\Users\SadeedBari\Documents\djangoproject\django_project\users\views.py changed, reloading.
Watching for file changes with StatReloader
Performing system checks...

System check identified no issues (0 silenced).
April 06, 2020 - 00:40:46
Django version 3.0.5, using settings 'django_project.settings'
Starting development server at http://127.0.0.1:8000/
Quit the server with CTRL-BREAK.
C:\Users\SadeedBari\Documents\djangoproject\django_project\users\views.py changed, reloading.
Watching for file changes with StatReloader
Performing system checks...

Exception in thread django-main-thread:
Traceback (most recent call last):
  File "C:\Users\SadeedBari\AppData\Local\Programs\Python\Python38-32\lib\threading.py", line 932, in _bootstrap_inner
    self.run()
  File "C:\Users\SadeedBari\AppData\Local\Programs\Python\Python38-32\lib\threading.py", line 870, in run
    self._target(*self._args, **self._kwargs)
  File "C:\Users\SadeedBari\AppData\Local\Programs\Python\Python38-32\lib\site-packages\django\utils\autoreload.py", line 53, in wrapper
    fn(*args, **kwargs)
  File "C:\Users\SadeedBari\AppData\Local\Programs\Python\Python38-32\lib\site-packages\django\core\management\commands\runserver.py", line 117, in inner_run
    self.check(display_num_errors=True)
  File "C:\Users\SadeedBari\AppData\Local\Programs\Python\Python38-32\lib\site-packages\django\core\management\base.py", line 392, in check
    all_issues = self._run_checks(
  File "C:\Users\SadeedBari\AppData\Local\Programs\Python\Python38-32\lib\site-packages\django\core\management\base.py", line 382, in _run_checks
    return checks.run_checks(**kwargs)
  File "C:\Users\SadeedBari\AppData\Local\Programs\Python\Python38-32\lib\site-packages\django\core\checks\registry.py", line 72, in run_checks
    new_errors = check(app_configs=app_configs)
  File "C:\Users\SadeedBari\AppData\Local\Programs\Python\Python38-32\lib\site-packages\django\core\checks\urls.py", line 13, in check_url_config
    return check_resolver(resolver)
  File "C:\Users\SadeedBari\AppData\Local\Programs\Python\Python38-32\lib\site-packages\django\core\checks\urls.py", line 23, in check_resolver
    return check_method()
  File "C:\Users\SadeedBari\AppData\Local\Programs\Python\Python38-32\lib\site-packages\django\urls\resolvers.py", line 407, in check
    for pattern in self.url_patterns:
  File "C:\Users\SadeedBari\AppData\Local\Programs\Python\Python38-32\lib\site-packages\django\utils\functional.py", line 48, in __get__
    res = instance.__dict__[self.name] = self.func(instance)
  File "C:\Users\SadeedBari\AppData\Local\Programs\Python\Python38-32\lib\site-packages\django\urls\resolvers.py", line 588, in url_patterns
    patterns = getattr(self.urlconf_module, "urlpatterns", self.urlconf_module)
  File "C:\Users\SadeedBari\AppData\Local\Programs\Python\Python38-32\lib\site-packages\django\utils\functional.py", line 48, in __get__
    res = instance.__dict__[self.name] = self.func(instance)
  File "C:\Users\SadeedBari\AppData\Local\Programs\Python\Python38-32\lib\site-packages\django\urls\resolvers.py", line 581, in urlconf_module
    return import_module(self.urlconf_name)
  File "C:\Users\SadeedBari\AppData\Local\Programs\Python\Python38-32\lib\importlib\__init__.py", line 127, in import_module
    return _bootstrap._gcd_import(name[level:], package, level)
  File "<frozen importlib._bootstrap>", line 1014, in _gcd_import
  File "<frozen importlib._bootstrap>", line 991, in _find_and_load
  File "<frozen importlib._bootstrap>", line 975, in _find_and_load_unlocked
  File "<frozen importlib._bootstrap>", line 671, in _load_unlocked
  File "<frozen importlib._bootstrap_external>", line 783, in exec_module
  File "<frozen importlib._bootstrap>", line 219, in _call_with_frames_removed
  File "C:\Users\SadeedBari\Documents\djangoproject\django_project\django_project\urls.py", line 18, in <module>
    from users import views as user_views
  File "C:\Users\SadeedBari\Documents\djangoproject\django_project\users\views.py", line 4
    from django import forms import UserRegisterForm
                             ^
SyntaxError: invalid syntax
C:\Users\SadeedBari\Documents\djangoproject\django_project\users\views.py changed, reloading.
Watching for file changes with StatReloader
Performing system checks...

Exception in thread django-main-thread:
Traceback (most recent call last):
  File "C:\Users\SadeedBari\AppData\Local\Programs\Python\Python38-32\lib\threading.py", line 932, in _bootstrap_inner
    self.run()
  File "C:\Users\SadeedBari\AppData\Local\Programs\Python\Python38-32\lib\threading.py", line 870, in run
    self._target(*self._args, **self._kwargs)
  File "C:\Users\SadeedBari\AppData\Local\Programs\Python\Python38-32\lib\site-packages\django\utils\autoreload.py", line 53, in wrapper
    fn(*args, **kwargs)
  File "C:\Users\SadeedBari\AppData\Local\Programs\Python\Python38-32\lib\site-packages\django\core\management\commands\runserver.py", line 117, in inner_run
    self.check(display_num_errors=True)
  File "C:\Users\SadeedBari\AppData\Local\Programs\Python\Python38-32\lib\site-packages\django\core\management\base.py", line 392, in check
    all_issues = self._run_checks(
  File "C:\Users\SadeedBari\AppData\Local\Programs\Python\Python38-32\lib\site-packages\django\core\management\base.py", line 382, in _run_checks
    return checks.run_checks(**kwargs)
  File "C:\Users\SadeedBari\AppData\Local\Programs\Python\Python38-32\lib\site-packages\django\core\checks\registry.py", line 72, in run_checks
    new_errors = check(app_configs=app_configs)
  File "C:\Users\SadeedBari\AppData\Local\Programs\Python\Python38-32\lib\site-packages\django\core\checks\urls.py", line 13, in check_url_config
    return check_resolver(resolver)
  File "C:\Users\SadeedBari\AppData\Local\Programs\Python\Python38-32\lib\site-packages\django\core\checks\urls.py", line 23, in check_resolver
    return check_method()
  File "C:\Users\SadeedBari\AppData\Local\Programs\Python\Python38-32\lib\site-packages\django\urls\resolvers.py", line 407, in check
    for pattern in self.url_patterns:
  File "C:\Users\SadeedBari\AppData\Local\Programs\Python\Python38-32\lib\site-packages\django\utils\functional.py", line 48, in __get__
    res = instance.__dict__[self.name] = self.func(instance)
  File "C:\Users\SadeedBari\AppData\Local\Programs\Python\Python38-32\lib\site-packages\django\urls\resolvers.py", line 588, in url_patterns
    patterns = getattr(self.urlconf_module, "urlpatterns", self.urlconf_module)
  File "C:\Users\SadeedBari\AppData\Local\Programs\Python\Python38-32\lib\site-packages\django\utils\functional.py", line 48, in __get__
    res = instance.__dict__[self.name] = self.func(instance)
  File "C:\Users\SadeedBari\AppData\Local\Programs\Python\Python38-32\lib\site-packages\django\urls\resolvers.py", line 581, in urlconf_module
    return import_module(self.urlconf_name)
  File "C:\Users\SadeedBari\AppData\Local\Programs\Python\Python38-32\lib\importlib\__init__.py", line 127, in import_module
    return _bootstrap._gcd_import(name[level:], package, level)
  File "<frozen importlib._bootstrap>", line 1014, in _gcd_import
  File "<frozen importlib._bootstrap>", line 991, in _find_and_load
  File "<frozen importlib._bootstrap>", line 975, in _find_and_load_unlocked
  File "<frozen importlib._bootstrap>", line 671, in _load_unlocked
  File "<frozen importlib._bootstrap_external>", line 783, in exec_module
  File "<frozen importlib._bootstrap>", line 219, in _call_with_frames_removed
  File "C:\Users\SadeedBari\Documents\djangoproject\django_project\django_project\urls.py", line 18, in <module>
    from users import views as user_views
  File "C:\Users\SadeedBari\Documents\djangoproject\django_project\users\views.py", line 4
    from django import forms import UserRegisterForm
                             ^
SyntaxError: invalid syntax
C:\Users\SadeedBari\Documents\djangoproject\django_project\users\views.py changed, reloading.
Watching for file changes with StatReloader
Performing system checks...

Exception in thread django-main-thread:
Traceback (most recent call last):
  File "C:\Users\SadeedBari\AppData\Local\Programs\Python\Python38-32\lib\threading.py", line 932, in _bootstrap_inner
    self.run()
  File "C:\Users\SadeedBari\AppData\Local\Programs\Python\Python38-32\lib\threading.py", line 870, in run
    self._target(*self._args, **self._kwargs)
  File "C:\Users\SadeedBari\AppData\Local\Programs\Python\Python38-32\lib\site-packages\django\utils\autoreload.py", line 53, in wrapper
    fn(*args, **kwargs)
  File "C:\Users\SadeedBari\AppData\Local\Programs\Python\Python38-32\lib\site-packages\django\core\management\commands\runserver.py", line 117, in inner_run
    self.check(display_num_errors=True)
  File "C:\Users\SadeedBari\AppData\Local\Programs\Python\Python38-32\lib\site-packages\django\core\management\base.py", line 392, in check
    all_issues = self._run_checks(
  File "C:\Users\SadeedBari\AppData\Local\Programs\Python\Python38-32\lib\site-packages\django\core\management\base.py", line 382, in _run_checks
    return checks.run_checks(**kwargs)
  File "C:\Users\SadeedBari\AppData\Local\Programs\Python\Python38-32\lib\site-packages\django\core\checks\registry.py", line 72, in run_checks
    new_errors = check(app_configs=app_configs)
  File "C:\Users\SadeedBari\AppData\Local\Programs\Python\Python38-32\lib\site-packages\django\core\checks\urls.py", line 13, in check_url_config
    return check_resolver(resolver)
  File "C:\Users\SadeedBari\AppData\Local\Programs\Python\Python38-32\lib\site-packages\django\core\checks\urls.py", line 23, in check_resolver
    return check_method()
  File "C:\Users\SadeedBari\AppData\Local\Programs\Python\Python38-32\lib\site-packages\django\urls\resolvers.py", line 407, in check
    for pattern in self.url_patterns:
  File "C:\Users\SadeedBari\AppData\Local\Programs\Python\Python38-32\lib\site-packages\django\utils\functional.py", line 48, in __get__
    res = instance.__dict__[self.name] = self.func(instance)
  File "C:\Users\SadeedBari\AppData\Local\Programs\Python\Python38-32\lib\site-packages\django\urls\resolvers.py", line 588, in url_patterns
    patterns = getattr(self.urlconf_module, "urlpatterns", self.urlconf_module)
  File "C:\Users\SadeedBari\AppData\Local\Programs\Python\Python38-32\lib\site-packages\django\utils\functional.py", line 48, in __get__
    res = instance.__dict__[self.name] = self.func(instance)
  File "C:\Users\SadeedBari\AppData\Local\Programs\Python\Python38-32\lib\site-packages\django\urls\resolvers.py", line 581, in urlconf_module
    return import_module(self.urlconf_name)
  File "C:\Users\SadeedBari\AppData\Local\Programs\Python\Python38-32\lib\importlib\__init__.py", line 127, in import_module
    return _bootstrap._gcd_import(name[level:], package, level)
  File "<frozen importlib._bootstrap>", line 1014, in _gcd_import
  File "<frozen importlib._bootstrap>", line 991, in _find_and_load
  File "<frozen importlib._bootstrap>", line 975, in _find_and_load_unlocked
  File "<frozen importlib._bootstrap>", line 671, in _load_unlocked
  File "<frozen importlib._bootstrap_external>", line 783, in exec_module
  File "<frozen importlib._bootstrap>", line 219, in _call_with_frames_removed
  File "C:\Users\SadeedBari\Documents\djangoproject\django_project\django_project\urls.py", line 18, in <module>
    from users import views as user_views
  File "C:\Users\SadeedBari\Documents\djangoproject\django_project\users\views.py", line 4, in <module>
    from .forms import UserRegisterForm
  File "C:\Users\SadeedBari\Documents\djangoproject\django_project\users\forms.py", line 5, in <module>
    class UserRegisterForm(UserCreationForm):
  File "C:\Users\SadeedBari\Documents\djangoproject\django_project\users\forms.py", line 7, in UserRegisterForm
    firstName = forms.firstName()
AttributeError: module 'django.forms' has no attribute 'firstName'
C:\Users\SadeedBari\Documents\djangoproject\django_project\users\forms.py changed, reloading.
Watching for file changes with StatReloader
Performing system checks...

Exception in thread django-main-thread:
Traceback (most recent call last):
  File "C:\Users\SadeedBari\AppData\Local\Programs\Python\Python38-32\lib\threading.py", line 932, in _bootstrap_inner
    self.run()
  File "C:\Users\SadeedBari\AppData\Local\Programs\Python\Python38-32\lib\threading.py", line 870, in run
    self._target(*self._args, **self._kwargs)
  File "C:\Users\SadeedBari\AppData\Local\Programs\Python\Python38-32\lib\site-packages\django\utils\autoreload.py", line 53, in wrapper
    fn(*args, **kwargs)
  File "C:\Users\SadeedBari\AppData\Local\Programs\Python\Python38-32\lib\site-packages\django\core\management\commands\runserver.py", line 117, in inner_run
    self.check(display_num_errors=True)
  File "C:\Users\SadeedBari\AppData\Local\Programs\Python\Python38-32\lib\site-packages\django\core\management\base.py", line 392, in check
    all_issues = self._run_checks(
  File "C:\Users\SadeedBari\AppData\Local\Programs\Python\Python38-32\lib\site-packages\django\core\management\base.py", line 382, in _run_checks
    return checks.run_checks(**kwargs)
  File "C:\Users\SadeedBari\AppData\Local\Programs\Python\Python38-32\lib\site-packages\django\core\checks\registry.py", line 72, in run_checks
    new_errors = check(app_configs=app_configs)
  File "C:\Users\SadeedBari\AppData\Local\Programs\Python\Python38-32\lib\site-packages\django\core\checks\urls.py", line 13, in check_url_config
    return check_resolver(resolver)
  File "C:\Users\SadeedBari\AppData\Local\Programs\Python\Python38-32\lib\site-packages\django\core\checks\urls.py", line 23, in check_resolver
    return check_method()
  File "C:\Users\SadeedBari\AppData\Local\Programs\Python\Python38-32\lib\site-packages\django\urls\resolvers.py", line 407, in check
    for pattern in self.url_patterns:
  File "C:\Users\SadeedBari\AppData\Local\Programs\Python\Python38-32\lib\site-packages\django\utils\functional.py", line 48, in __get__
    res = instance.__dict__[self.name] = self.func(instance)
  File "C:\Users\SadeedBari\AppData\Local\Programs\Python\Python38-32\lib\site-packages\django\urls\resolvers.py", line 588, in url_patterns
    patterns = getattr(self.urlconf_module, "urlpatterns", self.urlconf_module)
  File "C:\Users\SadeedBari\AppData\Local\Programs\Python\Python38-32\lib\site-packages\django\utils\functional.py", line 48, in __get__
    res = instance.__dict__[self.name] = self.func(instance)
  File "C:\Users\SadeedBari\AppData\Local\Programs\Python\Python38-32\lib\site-packages\django\urls\resolvers.py", line 581, in urlconf_module
    return import_module(self.urlconf_name)
  File "C:\Users\SadeedBari\AppData\Local\Programs\Python\Python38-32\lib\importlib\__init__.py", line 127, in import_module
    return _bootstrap._gcd_import(name[level:], package, level)
  File "<frozen importlib._bootstrap>", line 1014, in _gcd_import
  File "<frozen importlib._bootstrap>", line 991, in _find_and_load
  File "<frozen importlib._bootstrap>", line 975, in _find_and_load_unlocked
  File "<frozen importlib._bootstrap>", line 671, in _load_unlocked
  File "<frozen importlib._bootstrap_external>", line 783, in exec_module
  File "<frozen importlib._bootstrap>", line 219, in _call_with_frames_removed
  File "C:\Users\SadeedBari\Documents\djangoproject\django_project\django_project\urls.py", line 18, in <module>
    from users import views as user_views
  File "C:\Users\SadeedBari\Documents\djangoproject\django_project\users\views.py", line 4, in <module>
    from .forms import UserRegisterForm
  File "C:\Users\SadeedBari\Documents\djangoproject\django_project\users\forms.py", line 5, in <module>
    class UserRegisterForm(UserCreationForm):
  File "C:\Users\SadeedBari\AppData\Local\Programs\Python\Python38-32\lib\site-packages\django\forms\models.py", line 267, in __new__
    raise FieldError(message)
django.core.exceptions.FieldError: Unknown field(s) (Email) specified for User

C:\Users\SadeedBari\Documents\djangoproject\django_project>python manage.py runserver
Watching for file changes with StatReloader
Performing system checks...

System check identified no issues (0 silenced).
April 06, 2020 - 00:55:02
Django version 3.0.5, using settings 'django_project.settings'
Starting development server at http://127.0.0.1:8000/
Quit the server with CTRL-BREAK.
[06/Apr/2020 00:55:21] "GET /register/ HTTP/1.1" 200 4341
[06/Apr/2020 00:55:21] "GET /static/blog/main.css HTTP/1.1" 304 0
[06/Apr/2020 00:55:46] "POST /register/ HTTP/1.1" 302 0
[06/Apr/2020 00:55:46] "GET /blog/ HTTP/1.1" 200 3917
[06/Apr/2020 00:55:54] "GET /admin/ HTTP/1.1" 200 4010
[06/Apr/2020 00:55:54] "GET /static/admin/css/dashboard.css HTTP/1.1" 304 0
[06/Apr/2020 00:55:54] "GET /static/admin/css/base.css HTTP/1.1" 304 0
[06/Apr/2020 00:55:54] "GET /static/admin/css/responsive.css HTTP/1.1" 304 0
[06/Apr/2020 00:55:54] "GET /static/admin/css/fonts.css HTTP/1.1" 304 0
[06/Apr/2020 00:55:54] "GET /static/admin/img/icon-changelink.svg HTTP/1.1" 304 0
[06/Apr/2020 00:55:54] "GET /static/admin/img/icon-addlink.svg HTTP/1.1" 304 0
[06/Apr/2020 00:55:54] "GET /static/admin/fonts/Roboto-Regular-webfont.woff HTTP/1.1" 304 0
[06/Apr/2020 00:55:54] "GET /static/admin/fonts/Roboto-Light-webfont.woff HTTP/1.1" 304 0
[06/Apr/2020 00:55:54] "GET /static/admin/fonts/Roboto-Bold-webfont.woff HTTP/1.1" 304 0
[06/Apr/2020 00:55:56] "GET /admin/auth/user/ HTTP/1.1" 200 7464
[06/Apr/2020 00:55:56] "GET /static/admin/css/changelists.css HTTP/1.1" 304 0
[06/Apr/2020 00:55:56] "GET /static/admin/js/vendor/jquery/jquery.js HTTP/1.1" 304 0
[06/Apr/2020 00:55:56] "GET /static/admin/js/jquery.init.js HTTP/1.1" 304 0
[06/Apr/2020 00:55:56] "GET /static/admin/js/core.js HTTP/1.1" 304 0
[06/Apr/2020 00:55:56] "GET /static/admin/js/admin/RelatedObjectLookups.js HTTP/1.1" 304 0
[06/Apr/2020 00:55:56] "GET /static/admin/js/actions.js HTTP/1.1" 304 0
[06/Apr/2020 00:55:56] "GET /static/admin/js/urlify.js HTTP/1.1" 304 0
[06/Apr/2020 00:55:56] "GET /static/admin/js/prepopulate.js HTTP/1.1" 304 0
[06/Apr/2020 00:55:56] "GET /admin/jsi18n/ HTTP/1.1" 200 3223
[06/Apr/2020 00:55:56] "GET /static/admin/js/vendor/xregexp/xregexp.js HTTP/1.1" 304 0
[06/Apr/2020 00:55:56] "GET /static/admin/img/search.svg HTTP/1.1" 304 0
[06/Apr/2020 00:55:56] "GET /static/admin/img/icon-no.svg HTTP/1.1" 304 0
[06/Apr/2020 00:55:56] "GET /static/admin/img/icon-yes.svg HTTP/1.1" 304 0
[06/Apr/2020 00:55:57] "GET /static/admin/img/tooltag-add.svg HTTP/1.1" 304 0
[06/Apr/2020 00:55:57] "GET /static/admin/img/sorting-icons.svg HTTP/1.1" 304 0
[06/Apr/2020 00:56:21] "GET /register/ HTTP/1.1" 200 4341

C:\Users\SadeedBari\Documents\djangoproject\django_project>pip install django-crispy-forms
Collecting django-crispy-forms
  Downloading django_crispy_forms-1.9.0-py2.py3-none-any.whl (107 kB)
     |████████████████████████████████| 107 kB 1.3 MB/s
Installing collected packages: django-crispy-forms
Successfully installed django-crispy-forms-1.9.0

C:\Users\SadeedBari\Documents\djangoproject\django_project>python manage.py runserver
Watching for file changes with StatReloader
Performing system checks...

System check identified no issues (0 silenced).
April 06, 2020 - 01:01:05
Django version 3.0.5, using settings 'django_project.settings'
Starting development server at http://127.0.0.1:8000/
Quit the server with CTRL-BREAK.
[06/Apr/2020 01:01:13] "GET /register/ HTTP/1.1" 200 5184
[06/Apr/2020 01:02:38] "POST /register/ HTTP/1.1" 200 5485
[06/Apr/2020 01:07:10] "POST /register/ HTTP/1.1" 200 5485
[06/Apr/2020 01:07:13] "GET /register/ HTTP/1.1" 200 5184
[06/Apr/2020 01:07:32] "POST /register/ HTTP/1.1" 200 5474
[06/Apr/2020 01:08:17] "POST /register/ HTTP/1.1" 302 0
[06/Apr/2020 01:08:17] "GET /blog/ HTTP/1.1" 200 3916
C:\Users\SadeedBari\Documents\djangoproject\django_project\django_project\urls.py changed, reloading.
Watching for file changes with StatReloader
Performing system checks...

System check identified no issues (0 silenced).
April 06, 2020 - 01:30:07
Django version 3.0.5, using settings 'django_project.settings'
Starting development server at http://127.0.0.1:8000/
Quit the server with CTRL-BREAK.
[06/Apr/2020 01:30:41] "GET /login HTTP/1.1" 301 0
Internal Server Error: /login/
Traceback (most recent call last):
  File "C:\Users\SadeedBari\AppData\Local\Programs\Python\Python38-32\lib\site-packages\django\core\handlers\exception.py", line 34, in inner
    response = get_response(request)
  File "C:\Users\SadeedBari\AppData\Local\Programs\Python\Python38-32\lib\site-packages\django\core\handlers\base.py", line 145, in _get_response
    response = self.process_exception_by_middleware(e, request)
  File "C:\Users\SadeedBari\AppData\Local\Programs\Python\Python38-32\lib\site-packages\django\core\handlers\base.py", line 143, in _get_response
    response = response.render()
  File "C:\Users\SadeedBari\AppData\Local\Programs\Python\Python38-32\lib\site-packages\django\template\response.py", line 105, in render
    self.content = self.rendered_content
  File "C:\Users\SadeedBari\AppData\Local\Programs\Python\Python38-32\lib\site-packages\django\template\response.py", line 81, in rendered_content
    template = self.resolve_template(self.template_name)
  File "C:\Users\SadeedBari\AppData\Local\Programs\Python\Python38-32\lib\site-packages\django\template\response.py", line 63, in resolve_template
    return select_template(template, using=self.using)
  File "C:\Users\SadeedBari\AppData\Local\Programs\Python\Python38-32\lib\site-packages\django\template\loader.py", line 47, in select_template
    raise TemplateDoesNotExist(', '.join(template_name_list), chain=chain)
django.template.exceptions.TemplateDoesNotExist: registration/login.html
[06/Apr/2020 01:30:42] "GET /login/ HTTP/1.1" 500 81188
C:\Users\SadeedBari\Documents\djangoproject\django_project\django_project\urls.py changed, reloading.
Watching for file changes with StatReloader
Performing system checks...

System check identified no issues (0 silenced).
April 06, 2020 - 01:32:18
Django version 3.0.5, using settings 'django_project.settings'
Starting development server at http://127.0.0.1:8000/
Quit the server with CTRL-BREAK.
Internal Server Error: /login/
Traceback (most recent call last):
  File "C:\Users\SadeedBari\AppData\Local\Programs\Python\Python38-32\lib\site-packages\django\core\handlers\exception.py", line 34, in inner
    response = get_response(request)
  File "C:\Users\SadeedBari\AppData\Local\Programs\Python\Python38-32\lib\site-packages\django\core\handlers\base.py", line 145, in _get_response
    response = self.process_exception_by_middleware(e, request)
  File "C:\Users\SadeedBari\AppData\Local\Programs\Python\Python38-32\lib\site-packages\django\core\handlers\base.py", line 143, in _get_response
    response = response.render()
  File "C:\Users\SadeedBari\AppData\Local\Programs\Python\Python38-32\lib\site-packages\django\template\response.py", line 105, in render
    self.content = self.rendered_content
  File "C:\Users\SadeedBari\AppData\Local\Programs\Python\Python38-32\lib\site-packages\django\template\response.py", line 81, in rendered_content
    template = self.resolve_template(self.template_name)
  File "C:\Users\SadeedBari\AppData\Local\Programs\Python\Python38-32\lib\site-packages\django\template\response.py", line 63, in resolve_template
    return select_template(template, using=self.using)
  File "C:\Users\SadeedBari\AppData\Local\Programs\Python\Python38-32\lib\site-packages\django\template\loader.py", line 47, in select_template
    raise TemplateDoesNotExist(', '.join(template_name_list), chain=chain)
django.template.exceptions.TemplateDoesNotExist: users/login.html
[06/Apr/2020 01:32:18] "GET /login/ HTTP/1.1" 500 81199
[06/Apr/2020 01:36:17] "GET /login/ HTTP/1.1" 200 4025
[06/Apr/2020 01:36:17] "GET /static/blog/main.css HTTP/1.1" 304 0
[06/Apr/2020 01:37:28] "POST /login/ HTTP/1.1" 200 4215
C:\Users\SadeedBari\Documents\djangoproject\django_project\django_project\settings.py changed, reloading.
Watching for file changes with StatReloader
Performing system checks...

System check identified no issues (0 silenced).
April 06, 2020 - 01:39:21
Django version 3.0.5, using settings 'django_project.settings'
Starting development server at http://127.0.0.1:8000/
Quit the server with CTRL-BREAK.
[06/Apr/2020 01:39:26] "POST /login/ HTTP/1.1" 302 0
[06/Apr/2020 01:39:26] "GET /blog/ HTTP/1.1" 200 3816
[06/Apr/2020 01:39:56] "GET /admin/ HTTP/1.1" 200 4010
[06/Apr/2020 01:39:56] "GET /admin/ HTTP/1.1" 200 4010
[06/Apr/2020 01:40:00] "GET /admin/logout/ HTTP/1.1" 200 1207
[06/Apr/2020 01:40:09] "GET /admin/ HTTP/1.1" 302 0
[06/Apr/2020 01:40:09] "GET /admin/login/?next=/admin/ HTTP/1.1" 200 1913
[06/Apr/2020 01:40:09] "GET /admin/ HTTP/1.1" 302 0
[06/Apr/2020 01:40:09] "GET /admin/login/?next=/admin/ HTTP/1.1" 200 1913
[06/Apr/2020 01:40:09] "GET /static/admin/css/login.css HTTP/1.1" 304 0
[06/Apr/2020 01:40:16] "GET /login/ HTTP/1.1" 200 4025
C:\Users\SadeedBari\Documents\djangoproject\django_project\users\views.py changed, reloading.
Watching for file changes with StatReloader
Performing system checks...

System check identified no issues (0 silenced).
April 06, 2020 - 01:42:06
Django version 3.0.5, using settings 'django_project.settings'
Starting development server at http://127.0.0.1:8000/
Quit the server with CTRL-BREAK.
C:\Users\SadeedBari\Documents\djangoproject\django_project\django_project\urls.py changed, reloading.
Watching for file changes with StatReloader
Performing system checks...

System check identified no issues (0 silenced).
April 06, 2020 - 01:42:34
Django version 3.0.5, using settings 'django_project.settings'
Starting development server at http://127.0.0.1:8000/
Quit the server with CTRL-BREAK.
[06/Apr/2020 01:42:38] "POST /login/ HTTP/1.1" 302 0
[06/Apr/2020 01:42:39] "GET /blog/ HTTP/1.1" 200 3816
[06/Apr/2020 01:42:44] "GET /admin/ HTTP/1.1" 200 4010
[06/Apr/2020 01:42:45] "GET /admin/ HTTP/1.1" 200 4010
[06/Apr/2020 01:42:47] "GET /admin/logout/ HTTP/1.1" 200 1207
[06/Apr/2020 01:42:54] "GET /admin/ HTTP/1.1" 302 0
[06/Apr/2020 01:42:55] "GET /admin/login/?next=/admin/ HTTP/1.1" 200 1913
C:\Users\SadeedBari\Documents\djangoproject\django_project\django_project\urls.py changed, reloading.
Watching for file changes with StatReloader
Performing system checks...

System check identified no issues (0 silenced).
April 06, 2020 - 01:43:20
Django version 3.0.5, using settings 'django_project.settings'
Starting development server at http://127.0.0.1:8000/
Quit the server with CTRL-BREAK.
[06/Apr/2020 01:43:20] "GET /admin/login/?next=/admin/ HTTP/1.1" 200 1913
[06/Apr/2020 01:43:21] "GET /admin/logout/ HTTP/1.1" 302 0
[06/Apr/2020 01:43:21] "GET /admin/ HTTP/1.1" 302 0
[06/Apr/2020 01:43:21] "GET /admin/login/?next=/admin/ HTTP/1.1" 200 1913
[06/Apr/2020 01:43:24] "GET /admin/ HTTP/1.1" 302 0
[06/Apr/2020 01:43:24] "GET /admin/login/?next=/admin/ HTTP/1.1" 200 1913
[06/Apr/2020 01:43:26] "GET /login/ HTTP/1.1" 200 4025
[06/Apr/2020 01:46:43] "GET /blog/ HTTP/1.1" 200 3816
[06/Apr/2020 01:46:48] "GET /login/ HTTP/1.1" 200 4025
[06/Apr/2020 01:46:55] "POST /login/ HTTP/1.1" 302 0
[06/Apr/2020 01:46:55] "GET /blog/ HTTP/1.1" 200 3816
[06/Apr/2020 01:46:59] "GET /logout/ HTTP/1.1" 200 2938
[06/Apr/2020 01:47:02] "GET /login/ HTTP/1.1" 200 4025
[06/Apr/2020 01:47:38] "GET /logout/ HTTP/1.1" 200 2925
[06/Apr/2020 01:47:42] "GET /logout/ HTTP/1.1" 200 2925
[06/Apr/2020 01:48:05] "GET /admin/ HTTP/1.1" 302 0
[06/Apr/2020 01:48:05] "GET /admin/login/?next=/admin/ HTTP/1.1" 200 1913
Not Found: /
[06/Apr/2020 01:51:49] "GET / HTTP/1.1" 404 2402
[06/Apr/2020 01:51:52] "GET /blog/ HTTP/1.1" 200 3853
Not Found: /blog/{ url 'login'}
[06/Apr/2020 01:51:55] "GET /blog/%7B%20url%20'login'%7D HTTP/1.1" 404 2757
[06/Apr/2020 01:52:09] "GET /login/ HTTP/1.1" 200 4062
[06/Apr/2020 01:52:33] "GET /blog/ HTTP/1.1" 200 3853
Not Found: /blog/{ url 'register'}
[06/Apr/2020 01:52:35] "GET /blog/%7B%20url%20'register'%7D HTTP/1.1" 404 2766
[06/Apr/2020 01:53:43] "GET /login/ HTTP/1.1" 200 4062
[06/Apr/2020 01:53:50] "POST /login/ HTTP/1.1" 302 0
[06/Apr/2020 01:53:50] "GET /blog/ HTTP/1.1" 200 3782
Not Found: /blog/{ url 'logout'}
[06/Apr/2020 01:53:52] "GET /blog/%7B%20url%20'logout'%7D HTTP/1.1" 404 2760
[06/Apr/2020 01:55:19] "GET /blog/ HTTP/1.1" 200 3775
[06/Apr/2020 01:55:28] "GET /logout/ HTTP/1.1" 200 2948
[06/Apr/2020 01:55:30] "GET /login/ HTTP/1.1" 200 4048
[06/Apr/2020 01:55:33] "GET /register/ HTTP/1.1" 200 5213
[06/Apr/2020 01:55:35] "GET /login/ HTTP/1.1" 200 4048
C:\Users\SadeedBari\Documents\djangoproject\django_project\users\views.py changed, reloading.
Watching for file changes with StatReloader
Performing system checks...

System check identified no issues (0 silenced).
April 06, 2020 - 01:58:47
Django version 3.0.5, using settings 'django_project.settings'
Starting development server at http://127.0.0.1:8000/
Quit the server with CTRL-BREAK.
C:\Users\SadeedBari\Documents\djangoproject\django_project\django_project\urls.py changed, reloading.
Watching for file changes with StatReloader
Performing system checks...

System check identified no issues (0 silenced).
April 06, 2020 - 02:01:14
Django version 3.0.5, using settings 'django_project.settings'
Starting development server at http://127.0.0.1:8000/
Quit the server with CTRL-BREAK.
[06/Apr/2020 02:02:17] "GET /login/ HTTP/1.1" 200 4048
[06/Apr/2020 02:02:17] "GET /static/blog/main.css HTTP/1.1" 304 0
[06/Apr/2020 02:02:27] "POST /login/ HTTP/1.1" 302 0
[06/Apr/2020 02:02:27] "GET /blog/ HTTP/1.1" 200 3837
[06/Apr/2020 02:02:31] "GET /profile/ HTTP/1.1" 200 2795
C:\Users\SadeedBari\Documents\djangoproject\django_project\users\views.py changed, reloading.
Watching for file changes with StatReloader
Performing system checks...

System check identified no issues (0 silenced).
April 06, 2020 - 02:04:22
Django version 3.0.5, using settings 'django_project.settings'
Starting development server at http://127.0.0.1:8000/
Quit the server with CTRL-BREAK.
[06/Apr/2020 02:15:31] "GET /profile/ HTTP/1.1" 200 2795
[06/Apr/2020 02:15:34] "GET /logout/ HTTP/1.1" 200 2948
[06/Apr/2020 02:15:42] "GET /profile/ HTTP/1.1" 302 0
Not Found: /accounts/login/
[06/Apr/2020 02:15:43] "GET /accounts/login/?next=/profile/ HTTP/1.1" 404 2604
C:\Users\SadeedBari\Documents\djangoproject\django_project\django_project\settings.py changed, reloading.
Watching for file changes with StatReloader
Performing system checks...

System check identified no issues (0 silenced).
April 06, 2020 - 02:16:58
Django version 3.0.5, using settings 'django_project.settings'
Starting development server at http://127.0.0.1:8000/
Quit the server with CTRL-BREAK.
Not Found: /accounts/login/
[06/Apr/2020 02:16:58] "GET /accounts/login/?next=/profile/ HTTP/1.1" 404 2604
[06/Apr/2020 02:17:05] "GET /profile/ HTTP/1.1" 302 0
[06/Apr/2020 02:17:06] "GET /login/?next=/profile/ HTTP/1.1" 200 4048
[06/Apr/2020 02:17:58] "POST /login/?next=/profile/ HTTP/1.1" 302 0
[06/Apr/2020 02:17:58] "GET /profile/ HTTP/1.1" 200 2795
